Workbook

Sheet Overzicht
A1: Overzicht grondstoffen
A3: Man & Brouw | B3: BE0778.696.105
A4: entrepotnr:
A7: Granen | B7: aangekocht [kg] | C7: gebruikt [kg] | D7: voorraad [kg] | F7: Hop | G7: aangekocht [kg] | H7: gebruikt [kg] | I7: voorraad [kg] | K7: Toevoegingen | L7: aangekocht [kg] | M7: gebruikt [kg] | N7: voorraad | P7: Gist | Q7: aangekocht [kg] | R7: gebruikt [kg] | S7: voorraad | U7: Verpakkingen | V7: aangekocht | W7: gebruikt | X7: voorraad
A8: ='Grondstof soorten'!A7 -> Pilsmout | B8: =SUMIF(Granen!G6:G999,A8,Granen!J6:J99) -> 1550 | C8: =SUMIF(Granen!R6:R999,A8,Granen!S6:S999) -> 1500 | D8: =B8-C8 -> 50 | F8: ='Grondstof soorten'!C7 -> Mandarina Bavaria | G8: =SUMIF(Hop!$G$6:$G$999,F8,Hop!$J$6:$J$99) -> 3.6 | H8: =SUMIF(Hop!$R$6:$R$999,F8,Hop!$S$6:$S$999) -> 2.4 | I8: =G8-H8 -> 1.2 | K8: ='Grondstof soorten'!B7 -> Bruine suiker | L8: =SUMIF(Toevoegingen!$G$6:$G$999,K8,Toevoegingen!$J$6:$J$99) -> 20 | M8: =SUMIF(Toevoegingen!$R$6:$R$999,K8,Toevoegingen!$S$6:$S$999) -> 20 | N8: =L8-M8 -> 0 | P8: ='Grondstof soorten'!D7 -> S-04 | Q8: =SUMIF(Gist!$G$6:$G$999,P8,Gist!$J$6:$J$99) -> 1.2 | R8: =SUMIF(Gist!$R$6:$R$999,P8,Gist!$S$6:$S$999) -> 0.575 | S8: =Q8-R8 -> 0.625 | U8: ='Grondstof soorten'!E7 -> Fles vichy 33cl | V8: =SUMIF(Verpakkingen!$G$6:$G$999,U8,Verpakkingen!$J$6:$J$99) -> 11648 | W8: =SUMIF(Verpakkingen!$S$6:$S$999,U8,Verpakkingen!$T$6:$T$999) -> 10062 | X8: =V8-W8 -> 1586
A9: ='Grondstof soorten'!A8 -> Tarwemout | B9: =SUMIF(Granen!G7:G1000,A9,Granen!J7:J100) -> 450 | C9: =SUMIF(Granen!R7:R1000,A9,Granen!S7:S1000) -> 370 | D9: =B9-C9 -> 80 | F9: ='Grondstof soorten'!C8 -> Idaho7 | G9: =SUMIF(Hop!$G$6:$G$999,F9,Hop!$J$6:$J$99) -> 1.1 | H9: =SUMIF(Hop!$R$6:$R$999,F9,Hop!$S$6:$S$999) -> 1.1 | I9: =G9-H9 -> 0 | K9: ='Grondstof soorten'!B8 -> Witte suiker | L9: =SUMIF(Toevoegingen!$G$6:$G$999,K9,Toevoegingen!$J$6:$J$99) -> 51 | M9: =SUMIF(Toevoegingen!$R$6:$R$999,K9,Toevoegingen!$S$6:$S$999) -> 43 | N9: =L9-M9 -> 8 | P9: ='Grondstof soorten'!D8 -> Voss Kveik | Q9: =SUMIF(Gist!$G$6:$G$999,P9,Gist!$J$6:$J$99) -> 0.5 | R9: =SUMIF(Gist!$R$6:$R$999,P9,Gist!$S$6:$S$999) -> 0.5 | S9: =Q9-R9 -> 0 | U9: ='Grondstof soorten'!E8 -> keykeg 20l | V9: =SUMIF(Verpakkingen!$G$6:$G$999,U9,Verpakkingen!$J$6:$J$99) -> 166 | W9: =SUMIF(Verpakkingen!$S$6:$S$999,U9,Verpakkingen!$T$6:$T$999) -> 162 | X9: =V9-W9 -> 4
A10: ='Grondstof soorten'!A9 -> Munich | B10: =SUMIF(Granen!G8:G1001,A10,Granen!J8:J101) -> 75 | C10: =SUMIF(Granen!R8:R1001,A10,Granen!S8:S1001) -> 75 | D10: =B10-C10 -> 0 | F10: ='Grondstof soorten'!C9 -> Citra | G10: =SUMIF(Hop!$G$6:$G$999,F10,Hop!$J$6:$J$99) -> 1.1 | H10: =SUMIF(Hop!$R$6:$R$999,F10,Hop!$S$6:$S$999) -> 1.1 | I10: =G10-H10 -> 0 | K10: ='Grondstof soorten'!B9 -> Appelsienen | L10: =SUMIF(Toevoegingen!$G$6:$G$999,K10,Toevoegingen!$J$6:$J$99) -> 8 | M10: =SUMIF(Toevoegingen!$R$6:$R$999,K10,Toevoegingen!$S$6:$S$999) -> 8 | N10: =L10-M10 -> 0 | P10: ='Grondstof soorten'!D9 -> Verdant IPA | Q10: =SUMIF(Gist!$G$6:$G$999,P10,Gist!$J$6:$J$99) -> 0.055 | R10: =SUMIF(Gist!$R$6:$R$999,P10,Gist!$S$6:$S$999) -> 0.055 | S10: =Q10-R10 -> 0 | U10: ='Grondstof soorten'!E9 -> kroonkurk wit | V10: =SUMIF(Verpakkingen!$G$6:$G$999,U10,Verpakkingen!$J$6:$J$99) -> 12500 | W10: =SUMIF(Verpakkingen!$S$6:$S$999,U10,Verpakkingen!$T$6:$T$999) -> 11316 | X10: =V10-W10 -> 1184
A11: ='Grondstof soorten'!A10 -> Chocolate Dark | B11: =SUMIF(Granen!G9:G1002,A11,Granen!J9:J102) -> 9 | C11: =SUMIF(Granen!R9:R1002,A11,Granen!S9:S1002) -> 9 | D11: =B11-C11 -> 0 | F11: ='Grondstof soorten'!C10 -> Galaxy | G11: =SUMIF(Hop!$G$6:$G$999,F11,Hop!$J$6:$J$99) -> 0.2 | H11: =SUMIF(Hop!$R$6:$R$999,F11,Hop!$S$6:$S$999) -> 0.2 | I11: =G11-H11 -> 0 | K11: ='Grondstof soorten'!B10 -> Limoen | L11: =SUMIF(Toevoegingen!$G$6:$G$999,K11,Toevoegingen!$J$6:$J$99) -> 167 | M11: =SUMIF(Toevoegingen!$R$6:$R$999,K11,Toevoegingen!$S$6:$S$999) -> 167 | N11: =L11-M11 -> 0 | P11: ='Grondstof soorten'!D10 -> LP652 | Q11: =SUMIF(Gist!$G$6:$G$999,P11,Gist!$J$6:$J$99) -> 0.3 | R11: =SUMIF(Gist!$R$6:$R$999,P11,Gist!$S$6:$S$999) -> 0.283 | S11: =Q11-R11 -> 0.017 | U11: ='Grondstof soorten'!E10 -> Fles Longneck 33cl | V11: =SUMIF(Verpakkingen!$G$6:$G$999,U11,Verpakkingen!$J$6:$J$99) -> 816 | W11: =SUMIF(Verpakkingen!$S$6:$S$999,U11,Verpakkingen!$T$6:$T$999) -> 816 | X11: =V11-W11 -> 0
A12: ='Grondstof soorten'!A11 -> CaraAroma | B12: =SUMIF(Granen!G10:G1003,A12,Granen!J10:J103) -> 35 | C12: =SUMIF(Granen!R10:R1003,A12,Granen!S10:S1003) -> 35 | D12: =B12-C12 -> 0 | F12: ='Grondstof soorten'!C11 -> Styrian Dana | G12: =SUMIF(Hop!$G$6:$G$999,F12,Hop!$J$6:$J$99) -> 0.4 | H12: =SUMIF(Hop!$R$6:$R$999,F12,Hop!$S$6:$S$999) -> 0.4 | I12: =G12-H12 -> 0 | K12: ='Grondstof soorten'!B11 -> Grof zeezout | L12: =SUMIF(Toevoegingen!$G$6:$G$999,K12,Toevoegingen!$J$6:$J$99) -> 2 | M12: =SUMIF(Toevoegingen!$R$6:$R$999,K12,Toevoegingen!$S$6:$S$999) -> 1.635 | N12: =L12-M12 -> 0.365 | P12: ='Grondstof soorten'!D11 -> WB-06 | Q12: =SUMIF(Gist!$G$6:$G$999,P12,Gist!$J$6:$J$99) -> 0.5 | R12: =SUMIF(Gist!$R$6:$R$999,P12,Gist!$S$6:$S$999) -> 0.5 | S12: =Q12-R12 -> 0 | U12: ='Grondstof soorten'!E11 -> Dozen 24st APO | V12: =SUMIF(Verpakkingen!$G$6:$G$999,U12,Verpakkingen!$J$6:$J$99) -> 140 | W12: =SUMIF(Verpakkingen!$S$6:$S$999,U12,Verpakkingen!$T$6:$T$999) -> 47 | X12: =V12-W12 -> 93
A13: ='Grondstof soorten'!A12 -> Witte Haver | B13: =SUMIF(Granen!G11:G1004,A13,Granen!J11:J104) -> 40 | C13: =SUMIF(Granen!R11:R1004,A13,Granen!S11:S1004) -> 40 | D13: =B13-C13 -> 0 | F13: ='Grondstof soorten'!C12 -> Magnum | G13: =SUMIF(Hop!$G$6:$G$999,F13,Hop!$J$6:$J$99) -> 1 | H13: =SUMIF(Hop!$R$6:$R$999,F13,Hop!$S$6:$S$999) -> 1 | I13: =G13-H13 -> 0 | K13: ='Grondstof soorten'!B12 -> cacaobonen | L13: =SUMIF(Toevoegingen!$G$6:$G$999,K13,Toevoegingen!$J$6:$J$99) -> 4.05 | M13: =SUMIF(Toevoegingen!$R$6:$R$999,K13,Toevoegingen!$S$6:$S$999) -> 4.05 | N13: =L13-M13 -> 0 | P13: ='Grondstof soorten'!D12 -> BE-256 | Q13: =SUMIF(Gist!$G$6:$G$999,P13,Gist!$J$6:$J$99) -> 0.5 | R13: =SUMIF(Gist!$R$6:$R$999,P13,Gist!$S$6:$S$999) -> 0.5 | S13: =Q13-R13 -> 0 | U13: ='Grondstof soorten'!E12 -> Fles belge 75cl | V13: =SUMIF(Verpakkingen!$G$6:$G$999,U13,Verpakkingen!$J$6:$J$99) -> 264 | W13: =SUMIF(Verpakkingen!$S$6:$S$999,U13,Verpakkingen!$T$6:$T$999) -> 264 | X13: =V13-W13 -> 0
A14: ='Grondstof soorten'!A13 -> CaraGold | B14: =SUMIF(Granen!G12:G1005,A14,Granen!J12:J105) -> 30 | C14: =SUMIF(Granen!R12:R1005,A14,Granen!S12:S1005) -> 30 | D14: =B14-C14 -> 0 | F14: ='Grondstof soorten'!C13 -> Hallertau Blanc | G14: =SUMIF(Hop!$G$6:$G$999,F14,Hop!$J$6:$J$99) -> 7.9 | H14: =SUMIF(Hop!$R$6:$R$999,F14,Hop!$S$6:$S$999) -> 3.5 | I14: =G14-H14 -> 4.4 | K14: ='Grondstof soorten'!B13 -> Speculaaskruiden | L14: =SUMIF(Toevoegingen!$G$6:$G$999,K14,Toevoegingen!$J$6:$J$99) -> 0.4 | M14: =SUMIF(Toevoegingen!$R$6:$R$999,K14,Toevoegingen!$S$6:$S$999) -> 0.28 | N14: =L14-M14 -> 0.12 | P14: ='Grondstof soorten'!D13 -> S-33 | Q14: =SUMIF(Gist!$G$6:$G$999,P14,Gist!$J$6:$J$99) -> 0.9 | R14: =SUMIF(Gist!$R$6:$R$999,P14,Gist!$S$6:$S$999) -> 0.525 | S14: =Q14-R14 -> 0.375 | U14: ='Grondstof soorten'!E13 -> Doos trio 75cl | V14: =SUMIF(Verpakkingen!$G$6:$G$999,U14,Verpakkingen!$J$6:$J$99) -> 60 | W14: =SUMIF(Verpakkingen!$S$6:$S$999,U14,Verpakkingen!$T$6:$T$999) -> 60 | X14: =V14-W14 -> 0
A15: ='Grondstof soorten'!A14 -> CaraBody | B15: =SUMIF(Granen!G13:G1006,A15,Granen!J13:J106) -> 5 | C15: =SUMIF(Granen!R13:R1006,A15,Granen!S13:S1006) -> 5 | D15: =B15-C15 -> 0 | F15: ='Grondstof soorten'!C14 -> Styrian Dragon | G15: =SUMIF(Hop!$G$6:$G$999,F15,Hop!$J$6:$J$99) -> 0.1 | H15: =SUMIF(Hop!$R$6:$R$999,F15,Hop!$S$6:$S$999) -> 0 | I15: =G15-H15 -> 0.1 | K15: ='Grondstof soorten'!B14 -> Rabarber | L15: =SUMIF(Toevoegingen!$G$6:$G$999,K15,Toevoegingen!$J$6:$J$99) -> 25 | M15: =SUMIF(Toevoegingen!$R$6:$R$999,K15,Toevoegingen!$S$6:$S$999) -> 25 | N15: =L15-M15 -> 0 | P15: ='Grondstof soorten'!D14 -> US-05 | Q15: =SUMIF(Gist!$G$6:$G$999,P15,Gist!$J$6:$J$99) -> 0.7 | R15: =SUMIF(Gist!$R$6:$R$999,P15,Gist!$S$6:$S$999) -> 0.325 | S15: =Q15-R15 -> 0.375 | U15: ='Grondstof soorten'!E14 -> Corny keg 19l | V15: =SUMIF(Verpakkingen!$G$6:$G$999,U15,Verpakkingen!$J$6:$J$99) -> 6 | W15: =SUMIF(Verpakkingen!$S$6:$S$999,U15,Verpakkingen!$T$6:$T$999) -> 7 | X15: =V15-W15 -> -1
A16: ='Grondstof soorten'!A15 -> Biscuit | B16: =SUMIF(Granen!G14:G1007,A16,Granen!J14:J107) -> 51 | C16: =SUMIF(Granen!R14:R1007,A16,Granen!S14:S1007) -> 51 | D16: =B16-C16 -> 0 | F16: ='Grondstof soorten'!C15 -> Calista | G16: =SUMIF(Hop!$G$6:$G$999,F16,Hop!$J$6:$J$99) -> 5.2 | H16: =SUMIF(Hop!$R$6:$R$999,F16,Hop!$S$6:$S$999) -> 3.4 | I16: =G16-H16 -> 1.8 | K16: ='Grondstof soorten'!B15 -> Frambozen diepvries | L16: =SUMIF(Toevoegingen!$G$6:$G$999,K16,Toevoegingen!$J$6:$J$99) -> 32 | M16: =SUMIF(Toevoegingen!$R$6:$R$999,K16,Toevoegingen!$S$6:$S$999) -> 32 | N16: =L16-M16 -> 0 | P16: ='Grondstof soorten'!D15 -> Aspergillus Luchuensis | Q16: =SUMIF(Gist!$G$6:$G$999,P16,Gist!$J$6:$J$99) -> 0.003 | R16: =SUMIF(Gist!$R$6:$R$999,P16,Gist!$S$6:$S$999) -> 0.003 | S16: =Q16-R16 -> 0 | U16: ='Grondstof soorten'!E15 | V16: =SUMIF(Verpakkingen!$G$6:$G$999,U16,Verpakkingen!$J$6:$J$99) -> 0 | W16: =SUMIF(Verpakkingen!$S$6:$S$999,U16,Verpakkingen!$T$6:$T$999) -> 0 | X16: =V16-W16 -> 0
A17: ='Grondstof soorten'!A16 -> Tarwe | B17: =SUMIF(Granen!G15:G1008,A17,Granen!J15:J108) -> 300 | C17: =SUMIF(Granen!R15:R1008,A17,Granen!S15:S1008) -> 286 | D17: =B17-C17 -> 14 | F17: ='Grondstof soorten'!C16 -> Solero | G17: =SUMIF(Hop!$G$6:$G$999,F17,Hop!$J$6:$J$99) -> 0.1 | H17: =SUMIF(Hop!$R$6:$R$999,F17,Hop!$S$6:$S$999) -> 0 | I17: =G17-H17 -> 0.1 | K17: ='Grondstof soorten'!B16 -> yuzu aroma | L17: =SUMIF(Toevoegingen!$G$6:$G$999,K17,Toevoegingen!$J$6:$J$99) -> 0.05 | M17: =SUMIF(Toevoegingen!$R$6:$R$999,K17,Toevoegingen!$S$6:$S$999) -> 0.05 | N17: =L17-M17 -> 0 | P17: ='Grondstof soorten'!D16 -> BE-134 | Q17: =SUMIF(Gist!$G$6:$G$999,P17,Gist!$J$6:$J$99) -> 1 | R17: =SUMIF(Gist!$R$6:$R$999,P17,Gist!$S$6:$S$999) -> 0.5 | S17: =Q17-R17 -> 0.5 | U17: ='Grondstof soorten'!B43 -> Zwarte Peper Lampong | V17: =SUMIF(Verpakkingen!$G$6:$G$999,U17,Verpakkingen!$J$6:$J$99) -> 0 | W17: =SUMIF(Verpakkingen!$S$6:$S$999,U17,Verpakkingen!$T$6:$T$999) -> 0 | X17: =V17-W17 -> 0
A18: ='Grondstof soorten'!A17 -> Oud brood | B18: =SUMIF(Granen!G16:G1009,A18,Granen!J16:J109) -> 10 | C18: =SUMIF(Granen!R16:R1009,A18,Granen!S16:S1009) -> 10 | D18: =B18-C18 -> 0 | F18: ='Grondstof soorten'!C17 -> Barbe Rouge | G18: =SUMIF(Hop!$G$6:$G$999,F18,Hop!$J$6:$J$99) -> 2.6 | H18: =SUMIF(Hop!$R$6:$R$999,F18,Hop!$S$6:$S$999) -> 2.6 | I18: =G18-H18 -> 0 | K18: ='Grondstof soorten'!B17 -> oranjebloesem | L18: =SUMIF(Toevoegingen!$G$6:$G$999,K18,Toevoegingen!$J$6:$J$99) -> 0.4 | M18: =SUMIF(Toevoegingen!$R$6:$R$999,K18,Toevoegingen!$S$6:$S$999) -> 0.4 | N18: =L18-M18 -> 0 | P18: ='Grondstof soorten'!D17 -> cider M02 | Q18: =SUMIF(Gist!$G$6:$G$999,P18,Gist!$J$6:$J$99) -> 0.25 | R18: =SUMIF(Gist!$R$6:$R$999,P18,Gist!$S$6:$S$999) -> 0.25 | S18: =Q18-R18 -> 0 | U18: ='Grondstof soorten'!B44 -> Zwarte Peper Tellicherry | V18: =SUMIF(Verpakkingen!$G$6:$G$999,U18,Verpakkingen!$J$6:$J$99) -> 0 | W18: =SUMIF(Verpakkingen!$S$6:$S$999,U18,Verpakkingen!$T$6:$T$999) -> 0 | X18: =V18-W18 -> 0
A19: ='Grondstof soorten'!A18 -> Havervlokken | B19: =SUMIF(Granen!G17:G1010,A19,Granen!J17:J110) -> 110.8 | C19: =SUMIF(Granen!R17:R1010,A19,Granen!S17:S1010) -> 105.3 | D19: =B19-C19 -> 5.5 | G19: =SUMIF(Hop!$G$6:$G$999,F19,Hop!$J$6:$J$99) -> 0 | H19: =SUMIF(Hop!$R$6:$R$999,F19,Hop!$S$6:$S$999) -> 0 | I19: =G19-H19 -> 0 | K19: ='Grondstof soorten'!B18 -> Bhut Jolokia | L19: =SUMIF(Toevoegingen!$G$6:$G$999,K19,Toevoegingen!$J$6:$J$99) -> 0.01 | M19: =SUMIF(Toevoegingen!$R$6:$R$999,K19,Toevoegingen!$S$6:$S$999) -> 0.01 | N19: =L19-M19 -> 0 | P19: ='Grondstof soorten'!D18 -> Apres-Ski | Q19: =SUMIF(Gist!$G$6:$G$999,P19,Gist!$J$6:$J$99) -> 0.5 | R19: =SUMIF(Gist!$R$6:$R$999,P19,Gist!$S$6:$S$999) -> 0.5 | S19: =Q19-R19 -> 0 | U19: ='Grondstof soorten'!B45 -> Tasmaanse Bergpeper | V19: =SUMIF(Verpakkingen!$G$6:$G$999,U19,Verpakkingen!$J$6:$J$99) -> 0 | W19: =SUMIF(Verpakkingen!$S$6:$S$999,U19,Verpakkingen!$T$6:$T$999) -> 0 | X19: =V19-W19 -> 0
A20: ='Grondstof soorten'!A19 -> CaraAmber | B20: =SUMIF(Granen!G18:G1011,A20,Granen!J18:J111) -> 25 | C20: =SUMIF(Granen!R18:R1011,A20,Granen!S18:S1011) -> 25 | D20: =B20-C20 -> 0 | F20: ='Grondstof soorten'!C19 -> Nelson Sauvin | G20: =SUMIF(Hop!$G$6:$G$999,F20,Hop!$J$6:$J$99) -> 2 | H20: =SUMIF(Hop!$R$6:$R$999,F20,Hop!$S$6:$S$999) -> 2 | I20: =G20-H20 -> 0 | K20: ='Grondstof soorten'!B19 -> mandarijnen | L20: =SUMIF(Toevoegingen!$G$6:$G$999,K20,Toevoegingen!$J$6:$J$99) -> 4.6 | M20: =SUMIF(Toevoegingen!$R$6:$R$999,K20,Toevoegingen!$S$6:$S$999) -> 4.6 | N20: =L20-M20 -> 0 | P20: ='Grondstof soorten'!D19 | Q20: =SUMIF(Gist!$G$6:$G$999,P20,Gist!$J$6:$J$99) -> 0 | R20: =SUMIF(Gist!$R$6:$R$999,P20,Gist!$S$6:$S$999) -> 0 | S20: =Q20-R20 -> 0 | U20: ='Grondstof soorten'!E19 | V20: =SUMIF(Verpakkingen!$G$6:$G$999,U20,Verpakkingen!$J$6:$J$99) -> 0 | W20: =SUMIF(Verpakkingen!$S$6:$S$999,U20,Verpakkingen!$T$6:$T$999) -> 0 | X20: =V20-W20 -> 0
A21: ='Grondstof soorten'!A20 -> Caramel 30 | B21: =SUMIF(Granen!G19:G1012,A21,Granen!J19:J112) -> 5 | C21: =SUMIF(Granen!R19:R1012,A21,Granen!S19:S1012) -> 5 | D21: =B21-C21 -> 0 | F21: ='Grondstof soorten'!C20 -> Cashmere | G21: =SUMIF(Hop!$G$6:$G$999,F21,Hop!$J$6:$J$99) -> 1 | H21: =SUMIF(Hop!$R$6:$R$999,F21,Hop!$S$6:$S$999) -> 1 | I21: =G21-H21 -> 0 | K21: ='Grondstof soorten'!B20 -> mandarijn aroma | L21: =SUMIF(Toevoegingen!$G$6:$G$999,K21,Toevoegingen!$J$6:$J$99) -> 0.05 | M21: =SUMIF(Toevoegingen!$R$6:$R$999,K21,Toevoegingen!$S$6:$S$999) -> 0.05 | N21: =L21-M21 -> 0 | P21: ='Grondstof soorten'!D20 | Q21: =SUMIF(Gist!$G$6:$G$999,P21,Gist!$J$6:$J$99) -> 0 | R21: =SUMIF(Gist!$R$6:$R$999,P21,Gist!$S$6:$S$999) -> 0 | S21: =Q21-R21 -> 0 | U21: ='Grondstof soorten'!E20 | V21: =SUMIF(Verpakkingen!$G$6:$G$999,U21,Verpakkingen!$J$6:$J$99) -> 0 | W21: =SUMIF(Verpakkingen!$S$6:$S$999,U21,Verpakkingen!$T$6:$T$999) -> 0 | X21: =V21-W21 -> 0
A22: ='Grondstof soorten'!A21 -> parelgerst | B22: =SUMIF(Granen!G20:G1013,A22,Granen!J20:J113) -> 2 | C22: =SUMIF(Granen!R20:R1013,A22,Granen!S20:S1013) -> 1 | D22: =B22-C22 -> 1 | F22: ='Grondstof soorten'!C21 -> Sabro | G22: =SUMIF(Hop!$G$6:$G$999,F22,Hop!$J$6:$J$99) -> 1 | H22: =SUMIF(Hop!$R$6:$R$999,F22,Hop!$S$6:$S$999) -> 1 | I22: =G22-H22 -> 0 | K22: ='Grondstof soorten'!B21 -> Japanse duizendknoop | L22: =SUMIF(Toevoegingen!$G$6:$G$999,K22,Toevoegingen!$J$6:$J$99) -> 20 | M22: =SUMIF(Toevoegingen!$R$6:$R$999,K22,Toevoegingen!$S$6:$S$999) -> 20 | N22: =L22-M22 -> 0 | P22: ='Grondstof soorten'!D21 | Q22: =SUMIF(Gist!$G$6:$G$999,P22,Gist!$J$6:$J$99) -> 0 | R22: =SUMIF(Gist!$R$6:$R$999,P22,Gist!$S$6:$S$999) -> 0 | S22: =Q22-R22 -> 0 | U22: ='Grondstof soorten'!E21 | V22: =SUMIF(Verpakkingen!$G$6:$G$999,U22,Verpakkingen!$J$6:$J$99) -> 0 | W22: =SUMIF(Verpakkingen!$S$6:$S$999,U22,Verpakkingen!$T$6:$T$999) -> 0 | X22: =V22-W22 -> 0
A23: ='Grondstof soorten'!A22 -> Cara 50 MD | B23: =SUMIF(Granen!G21:G1014,A23,Granen!J21:J114) -> 25 | C23: =SUMIF(Granen!R21:R1014,A23,Granen!S21:S1014) -> 25 | D23: =B23-C23 -> 0 | F23: ='Grondstof soorten'!C22 -> Crystal | G23: =SUMIF(Hop!$G$6:$G$999,F23,Hop!$J$6:$J$99) -> 0.2 | H23: =SUMIF(Hop!$R$6:$R$999,F23,Hop!$S$6:$S$999) -> 0.2 | I23: =G23-H23 -> 0 | K23: ='Grondstof soorten'!B22 -> pompelmoes | L23: =SUMIF(Toevoegingen!$G$6:$G$999,K23,Toevoegingen!$J$6:$J$99) -> 7.53 | M23: =SUMIF(Toevoegingen!$R$6:$R$999,K23,Toevoegingen!$S$6:$S$999) -> 7.53 | N23: =L23-M23 -> 0 | P23: ='Grondstof soorten'!D22 | Q23: =SUMIF(Gist!$G$6:$G$999,P23,Gist!$J$6:$J$99) -> 0 | R23: =SUMIF(Gist!$R$6:$R$999,P23,Gist!$S$6:$S$999) -> 0 | S23: =Q23-R23 -> 0 | U23: ='Grondstof soorten'!E22 | V23: =SUMIF(Verpakkingen!$G$6:$G$999,U23,Verpakkingen!$J$6:$J$99) -> 0 | W23: =SUMIF(Verpakkingen!$S$6:$S$999,U23,Verpakkingen!$T$6:$T$999) -> 0 | X23: =V23-W23 -> 0
A24: ='Grondstof soorten'!A23 -> Sushi rijst | B24: =SUMIF(Granen!G22:G1015,A24,Granen!J22:J115) -> 15 | C24: =SUMIF(Granen!R22:R1015,A24,Granen!S22:S1015) -> 15 | D24: =B24-C24 -> 0 | F24: ='Grondstof soorten'!C23 -> Motueka | G24: =SUMIF(Hop!$G$6:$G$999,F24,Hop!$J$6:$J$99) -> 2 | H24: =SUMIF(Hop!$R$6:$R$999,F24,Hop!$S$6:$S$999) -> 2 | I24: =G24-H24 -> 0 | K24: ='Grondstof soorten'!B23 -> Kersen | L24: =SUMIF(Toevoegingen!$G$6:$G$999,K24,Toevoegingen!$J$6:$J$99) -> 37 | M24: =SUMIF(Toevoegingen!$R$6:$R$999,K24,Toevoegingen!$S$6:$S$999) -> 37 | N24: =L24-M24 -> 0 | P24: ='Grondstof soorten'!D23 | Q24: =SUMIF(Gist!$G$6:$G$999,P24,Gist!$J$6:$J$99) -> 0 | R24: =SUMIF(Gist!$R$6:$R$999,P24,Gist!$S$6:$S$999) -> 0 | S24: =Q24-R24 -> 0 | U24: ='Grondstof soorten'!E23 | V24: =SUMIF(Verpakkingen!$G$6:$G$999,U24,Verpakkingen!$J$6:$J$99) -> 0 | W24: =SUMIF(Verpakkingen!$S$6:$S$999,U24,Verpakkingen!$T$6:$T$999) -> 0 | X24: =V24-W24 -> 0
A25: ='Grondstof soorten'!A24 -> Spelt | B25: =SUMIF(Granen!G23:G1016,A25,Granen!J23:J116) -> 20 | C25: =SUMIF(Granen!R23:R1016,A25,Granen!S23:S1016) -> 0 | D25: =B25-C25 -> 20 | F25: ='Grondstof soorten'!C24 -> Hallertau Cascade | G25: =SUMIF(Hop!$G$6:$G$999,F25,Hop!$J$6:$J$99) -> 1 | H25: =SUMIF(Hop!$R$6:$R$999,F25,Hop!$S$6:$S$999) -> 1 | I25: =G25-H25 -> 0 | K25: ='Grondstof soorten'!B24 -> Tonkabonen | L25: =SUMIF(Toevoegingen!$G$6:$G$999,K25,Toevoegingen!$J$6:$J$99) -> 0.1 | M25: =SUMIF(Toevoegingen!$R$6:$R$999,K25,Toevoegingen!$S$6:$S$999) -> 0.075 | N25: =L25-M25 -> 0.025 | P25: ='Grondstof soorten'!D24 | Q25: =SUMIF(Gist!$G$6:$G$999,P25,Gist!$J$6:$J$99) -> 0 | R25: =SUMIF(Gist!$R$6:$R$999,P25,Gist!$S$6:$S$999) -> 0 | S25: =Q25-R25 -> 0 | U25: ='Grondstof soorten'!E24 | V25: =SUMIF(Verpakkingen!$G$6:$G$999,U25,Verpakkingen!$J$6:$J$99) -> 0 | W25: =SUMIF(Verpakkingen!$S$6:$S$999,U25,Verpakkingen!$T$6:$T$999) -> 0 | X25: =V25-W25 -> 0
A26: ='Grondstof soorten'!A25 -> rijsthulzen | B26: =SUMIF(Granen!G24:G1017,A26,Granen!J24:J117) -> 21 | C26: =SUMIF(Granen!R24:R1017,A26,Granen!S24:S1017) -> 14 | D26: =B26-C26 -> 7 | F26: ='Grondstof soorten'!C25 -> Styrian Kolibri | G26: =SUMIF(Hop!$G$6:$G$999,F26,Hop!$J$6:$J$99) -> 1 | H26: =SUMIF(Hop!$R$6:$R$999,F26,Hop!$S$6:$S$999) -> 1 | I26: =G26-H26 -> 0 | K26: ='Grondstof soorten'!B25 -> Pompelmoesmunt | L26: =SUMIF(Toevoegingen!$G$6:$G$999,K26,Toevoegingen!$J$6:$J$99) -> 7 | M26: =SUMIF(Toevoegingen!$R$6:$R$999,K26,Toevoegingen!$S$6:$S$999) -> 7 | N26: =L26-M26 -> 0 | P26: ='Grondstof soorten'!D25 | Q26: =SUMIF(Gist!$G$6:$G$999,P26,Gist!$J$6:$J$99) -> 0 | R26: =SUMIF(Gist!$R$6:$R$999,P26,Gist!$S$6:$S$999) -> 0 | S26: =Q26-R26 -> 0 | U26: ='Grondstof soorten'!E25 | V26: =SUMIF(Verpakkingen!$G$6:$G$999,U26,Verpakkingen!$J$6:$J$99) -> 0 | W26: =SUMIF(Verpakkingen!$S$6:$S$999,U26,Verpakkingen!$T$6:$T$999) -> 0 | X26: =V26-W26 -> 0
A27: ='Grondstof soorten'!A26 -> Carafa Special | B27: =SUMIF(Granen!G25:G1018,A27,Granen!J25:J118) -> 5 | C27: =SUMIF(Granen!R25:R1018,A27,Granen!S25:S1018) -> 2.5 | D27: =B27-C27 -> 2.5 | F27: ='Grondstof soorten'!C26 -> Bobek | G27: =SUMIF(Hop!$G$6:$G$999,F27,Hop!$J$6:$J$99) -> 1 | H27: =SUMIF(Hop!$R$6:$R$999,F27,Hop!$S$6:$S$999) -> 1 | I27: =G27-H27 -> 0 | K27: ='Grondstof soorten'!B26 -> King mints | L27: =SUMIF(Toevoegingen!$G$6:$G$999,K27,Toevoegingen!$J$6:$J$99) -> 6 | M27: =SUMIF(Toevoegingen!$R$6:$R$999,K27,Toevoegingen!$S$6:$S$999) -> 4 | N27: =L27-M27 -> 2 | P27: ='Grondstof soorten'!D26 | Q27: =SUMIF(Gist!$G$6:$G$999,P27,Gist!$J$6:$J$99) -> 0 | R27: =SUMIF(Gist!$R$6:$R$999,P27,Gist!$S$6:$S$999) -> 0 | S27: =Q27-R27 -> 0 | U27: ='Grondstof soorten'!E26 | V27: =SUMIF(Verpakkingen!$G$6:$G$999,U27,Verpakkingen!$J$6:$J$99) -> 0 | W27: =SUMIF(Verpakkingen!$S$6:$S$999,U27,Verpakkingen!$T$6:$T$999) -> 0 | X27: =V27-W27 -> 0
A28: ='Grondstof soorten'!A27 | B28: =SUMIF(Granen!G26:G1019,A28,Granen!J26:J119) -> 0 | C28: =SUMIF(Granen!R26:R1019,A28,Granen!S26:S1019) -> 0 | D28: =B28-C28 -> 0 | F28: ='Grondstof soorten'!C27 -> Talus | G28: =SUMIF(Hop!$G$6:$G$999,F28,Hop!$J$6:$J$99) -> 1 | H28: =SUMIF(Hop!$R$6:$R$999,F28,Hop!$S$6:$S$999) -> 1 | I28: =G28-H28 -> 0 | K28: ='Grondstof soorten'!B27 -> Green Sichuan Pepper | L28: =SUMIF(Toevoegingen!$G$6:$G$999,K28,Toevoegingen!$J$6:$J$99) -> 0.15 | M28: =SUMIF(Toevoegingen!$R$6:$R$999,K28,Toevoegingen!$S$6:$S$999) -> 0.15 | N28: =L28-M28 -> 0 | P28: ='Grondstof soorten'!D27 | Q28: =SUMIF(Gist!$G$6:$G$999,P28,Gist!$J$6:$J$99) -> 0 | R28: =SUMIF(Gist!$R$6:$R$999,P28,Gist!$S$6:$S$999) -> 0 | S28: =Q28-R28 -> 0 | U28: ='Grondstof soorten'!E27 | V28: =SUMIF(Verpakkingen!$G$6:$G$999,U28,Verpakkingen!$J$6:$J$99) -> 0 | W28: =SUMIF(Verpakkingen!$S$6:$S$999,U28,Verpakkingen!$T$6:$T$999) -> 0 | X28: =V28-W28 -> 0
A29: ='Grondstof soorten'!A28 | B29: =SUMIF(Granen!G27:G1020,A29,Granen!J27:J120) -> 0 | C29: =SUMIF(Granen!R27:R1020,A29,Granen!S27:S1020) -> 0 | D29: =B29-C29 -> 0 | F29: ='Grondstof soorten'!C28 -> Pacific Jade | G29: =SUMIF(Hop!$G$6:$G$999,F29,Hop!$J$6:$J$99) -> 1 | H29: =SUMIF(Hop!$R$6:$R$999,F29,Hop!$S$6:$S$999) -> 1 | I29: =G29-H29 -> 0 | K29: ='Grondstof soorten'!B28 -> groene thee | L29: =SUMIF(Toevoegingen!$G$6:$G$999,K29,Toevoegingen!$J$6:$J$99) -> 0.5 | M29: =SUMIF(Toevoegingen!$R$6:$R$999,K29,Toevoegingen!$S$6:$S$999) -> 0.5 | N29: =L29-M29 -> 0 | P29: ='Grondstof soorten'!D28 | Q29: =SUMIF(Gist!$G$6:$G$999,P29,Gist!$J$6:$J$99) -> 0 | R29: =SUMIF(Gist!$R$6:$R$999,P29,Gist!$S$6:$S$999) -> 0 | S29: =Q29-R29 -> 0 | U29: ='Grondstof soorten'!E28 | V29: =SUMIF(Verpakkingen!$G$6:$G$999,U29,Verpakkingen!$J$6:$J$99) -> 0 | W29: =SUMIF(Verpakkingen!$S$6:$S$999,U29,Verpakkingen!$T$6:$T$999) -> 0 | X29: =V29-W29 -> 0
A30: ='Grondstof soorten'!A29 | B30: =SUMIF(Granen!G28:G1021,A30,Granen!J28:J121) -> 0 | C30: =SUMIF(Granen!R27:R1021,A30,Granen!S27:S1021) -> 0 | D30: =B30-C30 -> 0 | F30: ='Grondstof soorten'!C29 -> Tuinhop | G30: =SUMIF(Hop!$G$6:$G$999,F30,Hop!$J$6:$J$99) -> 4 | H30: =SUMIF(Hop!$R$6:$R$999,F30,Hop!$S$6:$S$999) -> 4 | I30: =G30-H30 -> 0 | K30: ='Grondstof soorten'!B29 -> jasmijn | L30: =SUMIF(Toevoegingen!$G$6:$G$999,K30,Toevoegingen!$J$6:$J$99) -> 0.2 | M30: =SUMIF(Toevoegingen!$R$6:$R$999,K30,Toevoegingen!$S$6:$S$999) -> 0.2 | N30: =L30-M30 -> 0 | P30: ='Grondstof soorten'!D29 | Q30: =SUMIF(Gist!$G$6:$G$999,P30,Gist!$J$6:$J$99) -> 0 | R30: =SUMIF(Gist!$R$6:$R$999,P30,Gist!$S$6:$S$999) -> 0 | S30: =Q30-R30 -> 0 | U30: ='Grondstof soorten'!E29 | V30: =SUMIF(Verpakkingen!$G$6:$G$999,U30,Verpakkingen!$J$6:$J$99) -> 0 | W30: =SUMIF(Verpakkingen!$S$6:$S$999,U30,Verpakkingen!$T$6:$T$999) -> 0 | X30: =V30-W30 -> 0
A31: ='Grondstof soorten'!A30 | B31: =SUMIF(Granen!G29:G1022,A31,Granen!J29:J122) -> 0 | C31: =SUMIF(Granen!R29:R1022,A31,Granen!S29:S1022) -> 0 | D31: =B31-C31 -> 0 | F31: ='Grondstof soorten'!C30 -> Ariana | G31: =SUMIF(Hop!$G$6:$G$999,F31,Hop!$J$6:$J$99) -> 1 | H31: =SUMIF(Hop!$R$6:$R$999,F31,Hop!$S$6:$S$999) -> 1 | I31: =G31-H31 -> 0 | K31: ='Grondstof soorten'!B30 -> Kamillebloemen | L31: =SUMIF(Toevoegingen!$G$6:$G$999,K31,Toevoegingen!$J$6:$J$99) -> 0 | M31: =SUMIF(Toevoegingen!$R$6:$R$999,K31,Toevoegingen!$S$6:$S$999) -> 0 | N31: =L31-M31 -> 0 | P31: ='Grondstof soorten'!D30 | Q31: =SUMIF(Gist!$G$6:$G$999,P31,Gist!$J$6:$J$99) -> 0 | R31: =SUMIF(Gist!$R$6:$R$999,P31,Gist!$S$6:$S$999) -> 0 | S31: =Q31-R31 -> 0 | U31: ='Grondstof soorten'!E30 | V31: =SUMIF(Verpakkingen!$G$6:$G$999,U31,Verpakkingen!$J$6:$J$99) -> 0 | W31: =SUMIF(Verpakkingen!$S$6:$S$999,U31,Verpakkingen!$T$6:$T$999) -> 0 | X31: =V31-W31 -> 0
A32: ='Grondstof soorten'!A31 | B32: =SUMIF(Granen!G30:G1023,A32,Granen!J30:J123) -> 0 | C32: =SUMIF(Granen!R30:R1023,A32,Granen!S30:S1023) -> 0 | D32: =B32-C32 -> 0 | F32: ='Grondstof soorten'!C31 -> Tango | G32: =SUMIF(Hop!$G$6:$G$999,F32,Hop!$J$6:$J$99) -> 1 | H32: =SUMIF(Hop!$R$6:$R$999,F32,Hop!$S$6:$S$999) -> 1 | I32: =G32-H32 -> 0 | K32: ='Grondstof soorten'!B31 -> Bloedappelsiensap | L32: =SUMIF(Toevoegingen!$G$6:$G$999,K32,Toevoegingen!$J$6:$J$99) -> 12 | M32: =SUMIF(Toevoegingen!$R$6:$R$999,K32,Toevoegingen!$S$6:$S$999) -> 12 | N32: =L32-M32 -> 0 | P32: ='Grondstof soorten'!D31 | Q32: =SUMIF(Gist!$G$6:$G$999,P32,Gist!$J$6:$J$99) -> 0 | R32: =SUMIF(Gist!$R$6:$R$999,P32,Gist!$S$6:$S$999) -> 0 | S32: =Q32-R32 -> 0 | U32: ='Grondstof soorten'!E31 | V32: =SUMIF(Verpakkingen!$G$6:$G$999,U32,Verpakkingen!$J$6:$J$99) -> 0 | W32: =SUMIF(Verpakkingen!$S$6:$S$999,U32,Verpakkingen!$T$6:$T$999) -> 0 | X32: =V32-W32 -> 0
A33: ='Grondstof soorten'!A32 | B33: =SUMIF(Granen!G31:G1024,A33,Granen!J31:J124) -> 0 | C33: =SUMIF(Granen!R31:R1024,A33,Granen!S31:S1024) -> 0 | D33: =B33-C33 -> 0 | F33: ='Grondstof soorten'!C32 | G33: =SUMIF(Hop!$G$6:$G$999,F33,Hop!$J$6:$J$99) -> 0 | H33: =SUMIF(Hop!$R$6:$R$999,F33,Hop!$S$6:$S$999) -> 0 | I33: =G33-H33 -> 0 | K33: ='Grondstof soorten'!B32 -> Bloedappelsienen | L33: =SUMIF(Toevoegingen!$G$6:$G$999,K33,Toevoegingen!$J$6:$J$99) -> 12 | M33: =SUMIF(Toevoegingen!$R$6:$R$999,K33,Toevoegingen!$S$6:$S$999) -> 12 | N33: =L33-M33 -> 0 | P33: ='Grondstof soorten'!D32 | Q33: =SUMIF(Gist!$G$6:$G$999,P33,Gist!$J$6:$J$99) -> 0 | R33: =SUMIF(Gist!$R$6:$R$999,P33,Gist!$S$6:$S$999) -> 0 | S33: =Q33-R33 -> 0 | U33: ='Grondstof soorten'!E32 | V33: =SUMIF(Verpakkingen!$G$6:$G$999,U33,Verpakkingen!$J$6:$J$99) -> 0 | W33: =SUMIF(Verpakkingen!$S$6:$S$999,U33,Verpakkingen!$T$6:$T$999) -> 0 | X33: =V33-W33 -> 0
A34: ='Grondstof soorten'!A33 | B34: =SUMIF(Granen!G32:G1025,A34,Granen!J32:J125) -> 0 | C34: =SUMIF(Granen!R32:R1025,A34,Granen!S32:S1025) -> 0 | D34: =B34-C34 -> 0 | F34: ='Grondstof soorten'!C33 | G34: =SUMIF(Hop!$G$6:$G$999,F34,Hop!$J$6:$J$99) -> 0 | H34: =SUMIF(Hop!$R$6:$R$999,F34,Hop!$S$6:$S$999) -> 0 | I34: =G34-H34 -> 0 | K34: ='Grondstof soorten'!B33 -> koffie | L34: =SUMIF(Toevoegingen!$G$6:$G$999,K34,Toevoegingen!$J$6:$J$99) -> 1 | M34: =SUMIF(Toevoegingen!$R$6:$R$999,K34,Toevoegingen!$S$6:$S$999) -> 1 | N34: =L34-M34 -> 0 | P34: ='Grondstof soorten'!D33 | Q34: =SUMIF(Gist!$G$6:$G$999,P34,Gist!$J$6:$J$99) -> 0 | R34: =SUMIF(Gist!$R$6:$R$999,P34,Gist!$S$6:$S$999) -> 0 | S34: =Q34-R34 -> 0 | U34: ='Grondstof soorten'!E33 | V34: =SUMIF(Verpakkingen!$G$6:$G$999,U34,Verpakkingen!$J$6:$J$99) -> 0 | W34: =SUMIF(Verpakkingen!$S$6:$S$999,U34,Verpakkingen!$T$6:$T$999) -> 0 | X34: =V34-W34 -> 0
A35: ='Grondstof soorten'!A34 | B35: =SUMIF(Granen!G33:G1026,A35,Granen!J33:J126) -> 0 | C35: =SUMIF(Granen!R33:R1026,A35,Granen!S33:S1026) -> 0 | D35: =B35-C35 -> 0 | F35: ='Grondstof soorten'!C34 | G35: =SUMIF(Hop!$G$6:$G$999,F35,Hop!$J$6:$J$99) -> 0 | H35: =SUMIF(Hop!$R$6:$R$999,F35,Hop!$S$6:$S$999) -> 0 | I35: =G35-H35 -> 0 | K35: ='Grondstof soorten'!B34 -> vanille | L35: =SUMIF(Toevoegingen!$G$6:$G$999,K35,Toevoegingen!$J$6:$J$99) -> 0.048 | M35: =SUMIF(Toevoegingen!$R$6:$R$999,K35,Toevoegingen!$S$6:$S$999) -> 0.048 | N35: =L35-M35 -> 0 | P35: ='Grondstof soorten'!D34 | Q35: =SUMIF(Gist!$G$6:$G$999,P35,Gist!$J$6:$J$99) -> 0 | R35: =SUMIF(Gist!$R$6:$R$999,P35,Gist!$S$6:$S$999) -> 0 | S35: =Q35-R35 -> 0 | U35: ='Grondstof soorten'!E34 | V35: =SUMIF(Verpakkingen!$G$6:$G$999,U35,Verpakkingen!$J$6:$J$99) -> 0 | W35: =SUMIF(Verpakkingen!$S$6:$S$999,U35,Verpakkingen!$T$6:$T$999) -> 0 | X35: =V35-W35 -> 0
A36: ='Grondstof soorten'!A35 | B36: =SUMIF(Granen!G34:G1027,A36,Granen!J34:J127) -> 0 | C36: =SUMIF(Granen!R34:R1027,A36,Granen!S34:S1027) -> 0 | D36: =B36-C36 -> 0 | F36: ='Grondstof soorten'!C35 | G36: =SUMIF(Hop!$G$6:$G$999,F36,Hop!$J$6:$J$99) -> 0 | H36: =SUMIF(Hop!$R$6:$R$999,F36,Hop!$S$6:$S$999) -> 0 | I36: =G36-H36 -> 0 | K36: ='Grondstof soorten'!B35 -> appelsap | L36: =SUMIF(Toevoegingen!$G$6:$G$999,K36,Toevoegingen!$J$6:$J$99) -> 180 | M36: =SUMIF(Toevoegingen!$R$6:$R$999,K36,Toevoegingen!$S$6:$S$999) -> 180 | N36: =L36-M36 -> 0 | P36: ='Grondstof soorten'!D35 | Q36: =SUMIF(Gist!$G$6:$G$999,P36,Gist!$J$6:$J$99) -> 0 | R36: =SUMIF(Gist!$R$6:$R$999,P36,Gist!$S$6:$S$999) -> 0 | S36: =Q36-R36 -> 0 | U36: ='Grondstof soorten'!E35 | V36: =SUMIF(Verpakkingen!$G$6:$G$999,U36,Verpakkingen!$J$6:$J$99) -> 0 | W36: =SUMIF(Verpakkingen!$S$6:$S$999,U36,Verpakkingen!$T$6:$T$999) -> 0 | X36: =V36-W36 -> 0
A37: ='Grondstof soorten'!A36 | B37: =SUMIF(Granen!G35:G1028,A37,Granen!J35:J128) -> 0 | C37: =SUMIF(Granen!R35:R1028,A37,Granen!S35:S1028) -> 0 | D37: =B37-C37 -> 0 | F37: ='Grondstof soorten'!C36 | G37: =SUMIF(Hop!$G$6:$G$999,F37,Hop!$J$6:$J$99) -> 0 | H37: =SUMIF(Hop!$R$6:$R$999,F37,Hop!$S$6:$S$999) -> 0 | I37: =G37-H37 -> 0 | K37: ='Grondstof soorten'!B36 -> Gember | L37: =SUMIF(Toevoegingen!$G$6:$G$999,K37,Toevoegingen!$J$6:$J$99) -> 2.36 | M37: =SUMIF(Toevoegingen!$R$6:$R$999,K37,Toevoegingen!$S$6:$S$999) -> 2.36 | N37: =L37-M37 -> 0 | P37: ='Grondstof soorten'!D36 | Q37: =SUMIF(Gist!$G$6:$G$999,P37,Gist!$J$6:$J$99) -> 0 | R37: =SUMIF(Gist!$R$6:$R$999,P37,Gist!$S$6:$S$999) -> 0 | S37: =Q37-R37 -> 0 | U37: ='Grondstof soorten'!E36 | V37: =SUMIF(Verpakkingen!$G$6:$G$999,U37,Verpakkingen!$J$6:$J$99) -> 0 | W37: =SUMIF(Verpakkingen!$S$6:$S$999,U37,Verpakkingen!$T$6:$T$999) -> 0 | X37: =V37-W37 -> 0
A38: ='Grondstof soorten'!A37 | B38: =SUMIF(Granen!G36:G1029,A38,Granen!J36:J129) -> 0 | C38: =SUMIF(Granen!R36:R1029,A38,Granen!S36:S1029) -> 0 | D38: =B38-C38 -> 0 | F38: ='Grondstof soorten'!C37 | G38: =SUMIF(Hop!$G$6:$G$999,F38,Hop!$J$6:$J$99) -> 0 | H38: =SUMIF(Hop!$R$6:$R$999,F38,Hop!$S$6:$S$999) -> 0 | I38: =G38-H38 -> 0 | K38: ='Grondstof soorten'!B37 -> Citroengras | L38: =SUMIF(Toevoegingen!$G$6:$G$999,K38,Toevoegingen!$J$6:$J$99) -> 0.84 | M38: =SUMIF(Toevoegingen!$R$6:$R$999,K38,Toevoegingen!$S$6:$S$999) -> 0.84 | N38: =L38-M38 -> 0 | P38: ='Grondstof soorten'!D37 | Q38: =SUMIF(Gist!$G$6:$G$999,P38,Gist!$J$6:$J$99) -> 0 | R38: =SUMIF(Gist!$R$6:$R$999,P38,Gist!$S$6:$S$999) -> 0 | S38: =Q38-R38 -> 0 | U38: ='Grondstof soorten'!E37 | V38: =SUMIF(Verpakkingen!$G$6:$G$999,U38,Verpakkingen!$J$6:$J$99) -> 0 | W38: =SUMIF(Verpakkingen!$S$6:$S$999,U38,Verpakkingen!$T$6:$T$999) -> 0 | X38: =V38-W38 -> 0
A39: ='Grondstof soorten'!A38 | B39: =SUMIF(Granen!G37:G1030,A39,Granen!J37:J130) -> 0 | C39: =SUMIF(Granen!R37:R1030,A39,Granen!S37:S1030) -> 0 | D39: =B39-C39 -> 0 | F39: ='Grondstof soorten'!C38 | G39: =SUMIF(Hop!$G$6:$G$999,F39,Hop!$J$6:$J$99) -> 0 | H39: =SUMIF(Hop!$R$6:$R$999,F39,Hop!$S$6:$S$999) -> 0 | I39: =G39-H39 -> 0 | K39: ='Grondstof soorten'!B38 -> kokosnoot | L39: =SUMIF(Toevoegingen!$G$6:$G$999,K39,Toevoegingen!$J$6:$J$99) -> 4 | M39: =SUMIF(Toevoegingen!$R$6:$R$999,K39,Toevoegingen!$S$6:$S$999) -> 4 | N39: =L39-M39 -> 0 | P39: ='Grondstof soorten'!D38 | Q39: =SUMIF(Gist!$G$6:$G$999,P39,Gist!$J$6:$J$99) -> 0 | R39: =SUMIF(Gist!$R$6:$R$999,P39,Gist!$S$6:$S$999) -> 0 | S39: =Q39-R39 -> 0 | U39: ='Grondstof soorten'!E38 | V39: =SUMIF(Verpakkingen!$G$6:$G$999,U39,Verpakkingen!$J$6:$J$99) -> 0 | W39: =SUMIF(Verpakkingen!$S$6:$S$999,U39,Verpakkingen!$T$6:$T$999) -> 0 | X39: =V39-W39 -> 0
A40: ='Grondstof soorten'!A39 | B40: =SUMIF(Granen!G38:G1031,A40,Granen!J38:J131) -> 0 | C40: =SUMIF(Granen!R38:R1031,A40,Granen!S38:S1031) -> 0 | D40: =B40-C40 -> 0 | F40: ='Grondstof soorten'!C39 | G40: =SUMIF(Hop!$G$6:$G$999,F40,Hop!$J$6:$J$99) -> 0 | H40: =SUMIF(Hop!$R$6:$R$999,F40,Hop!$S$6:$S$999) -> 0 | I40: =G40-H40 -> 0 | K40: ='Grondstof soorten'!B39 -> abrikoos | L40: =SUMIF(Toevoegingen!$G$6:$G$999,K40,Toevoegingen!$J$6:$J$99) -> 40 | M40: =SUMIF(Toevoegingen!$R$6:$R$999,K40,Toevoegingen!$S$6:$S$999) -> 40 | N40: =L40-M40 -> 0 | P40: ='Grondstof soorten'!D39 | Q40: =SUMIF(Gist!$G$6:$G$999,P40,Gist!$J$6:$J$99) -> 0 | R40: =SUMIF(Gist!$R$6:$R$999,P40,Gist!$S$6:$S$999) -> 0 | S40: =Q40-R40 -> 0 | U40: ='Grondstof soorten'!E39 | V40: =SUMIF(Verpakkingen!$G$6:$G$999,U40,Verpakkingen!$J$6:$J$99) -> 0 | W40: =SUMIF(Verpakkingen!$S$6:$S$999,U40,Verpakkingen!$T$6:$T$999) -> 0 | X40: =V40-W40 -> 0
A41: ='Grondstof soorten'!A40 | B41: =SUMIF(Granen!G39:G1032,A41,Granen!J39:J132) -> 0 | C41: =SUMIF(Granen!R39:R1032,A41,Granen!S39:S1032) -> 0 | D41: =B41-C41 -> 0 | F41: ='Grondstof soorten'!C40 | G41: =SUMIF(Hop!$G$6:$G$999,F41,Hop!$J$6:$J$99) -> 0 | H41: =SUMIF(Hop!$R$6:$R$999,F41,Hop!$S$6:$S$999) -> 0 | I41: =G41-H41 -> 0 | K41: ='Grondstof soorten'!B40 -> citroen | L41: =SUMIF(Toevoegingen!$G$6:$G$999,K41,Toevoegingen!$J$6:$J$99) -> 18.7 | M41: =SUMIF(Toevoegingen!$R$6:$R$999,K41,Toevoegingen!$S$6:$S$999) -> 18.7 | N41: =L41-M41 -> 0 | P41: ='Grondstof soorten'!D40 | Q41: =SUMIF(Gist!$G$6:$G$999,P41,Gist!$J$6:$J$99) -> 0 | R41: =SUMIF(Gist!$R$6:$R$999,P41,Gist!$S$6:$S$999) -> 0 | S41: =Q41-R41 -> 0 | U41: ='Grondstof soorten'!E40 | V41: =SUMIF(Verpakkingen!$G$6:$G$999,U41,Verpakkingen!$J$6:$J$99) -> 0 | W41: =SUMIF(Verpakkingen!$S$6:$S$999,U41,Verpakkingen!$T$6:$T$999) -> 0 | X41: =V41-W41 -> 0
A42: ='Grondstof soorten'!A41 | B42: =SUMIF(Granen!G40:G1033,A42,Granen!J40:J133) -> 0 | C42: =SUMIF(Granen!R40:R1033,A42,Granen!S40:S1033) -> 0 | D42: =B42-C42 -> 0 | F42: ='Grondstof soorten'!C41 | G42: =SUMIF(Hop!$G$6:$G$999,F42,Hop!$J$6:$J$99) -> 0 | H42: =SUMIF(Hop!$R$6:$R$999,F42,Hop!$S$6:$S$999) -> 0 | I42: =G42-H42 -> 0 | K42: ='Grondstof soorten'!B41 -> aardbei | L42: =SUMIF(Toevoegingen!$G$6:$G$999,K42,Toevoegingen!$J$6:$J$99) -> 50 | M42: =SUMIF(Toevoegingen!$R$6:$R$999,K42,Toevoegingen!$S$6:$S$999) -> 50 | N42: =L42-M42 -> 0 | P42: ='Grondstof soorten'!D41 | Q42: =SUMIF(Gist!$G$6:$G$999,P42,Gist!$J$6:$J$99) -> 0 | R42: =SUMIF(Gist!$R$6:$R$999,P42,Gist!$S$6:$S$999) -> 0 | S42: =Q42-R42 -> 0 | U42: ='Grondstof soorten'!E41 | V42: =SUMIF(Verpakkingen!$G$6:$G$999,U42,Verpakkingen!$J$6:$J$99) -> 0 | W42: =SUMIF(Verpakkingen!$S$6:$S$999,U42,Verpakkingen!$T$6:$T$999) -> 0 | X42: =V42-W42 -> 0
A43: ='Grondstof soorten'!A42 | B43: =SUMIF(Granen!G41:G1034,A43,Granen!J41:J134) -> 0 | C43: =SUMIF(Granen!R41:R1034,A43,Granen!S41:S1034) -> 0 | D43: =B43-C43 -> 0 | F43: ='Grondstof soorten'!C42 | G43: =SUMIF(Hop!$G$6:$G$999,F43,Hop!$J$6:$J$99) -> 0 | H43: =SUMIF(Hop!$R$6:$R$999,F43,Hop!$S$6:$S$999) -> 0 | I43: =G43-H43 -> 0 | K43: ='Grondstof soorten'!B42 -> hotsauce | L43: =SUMIF(Toevoegingen!$G$6:$G$999,K43,Toevoegingen!$J$6:$J$99) -> 1 | M43: =SUMIF(Toevoegingen!$R$6:$R$999,K43,Toevoegingen!$S$6:$S$999) -> 1 | N43: =L43-M43 -> 0 | P43: ='Grondstof soorten'!D42 | Q43: =SUMIF(Gist!$G$6:$G$999,P43,Gist!$J$6:$J$99) -> 0 | R43: =SUMIF(Gist!$R$6:$R$999,P43,Gist!$S$6:$S$999) -> 0 | S43: =Q43-R43 -> 0 | U43: ='Grondstof soorten'!E42 | V43: =SUMIF(Verpakkingen!$G$6:$G$999,U43,Verpakkingen!$J$6:$J$99) -> 0 | W43: =SUMIF(Verpakkingen!$S$6:$S$999,U43,Verpakkingen!$T$6:$T$999) -> 0 | X43: =V43-W43 -> 0
...

Sheet Leveranciers
A1: Lijst van leveranciers
A3: Naam | B3: Adres | C3: contactpersoon | D3: telefoon | E3: mail | F3: KBO | G3: FAVV registratienummer
A4: LV Janssens - Dormaalhof | B4: Caubergstraat 2 3150 Haacht | C4: Dries Janssens | D4: 0497359423 | E4: dries@hoftendormaal.com | F4: BE0560669797 | G4: 2.234.204.958
A5: Brouwland BV | B5: Korpelsesteenweg 86 3581 Beverlo | D5: 011401408 | E5: profsales@brouwland.com | F5: BE0412461618 | G5: 2.038.594.164
A6: HVB-IMTC BV | B6: Kasteelstraat 21 9870 Olsene | D6: 092302770 | E6: info@hvb-imtc.be | F6: BE0693813779 | G6: 2.274.409.775
A7: Brouwerij De Coureur | B7: Borstelstraat 20 bus 001 3010 Kessel-Lo | C7: Bart Delvaux | D7: 0485178695 | E7: brouwerijdecoureur@gmail.com | F7: BE0713410551 | G7: 2.281.451.282
A8: Solucious SA NV | B8: Edingensesteenweg 196 1500 Halle | D8: 023338888 | E8: info@solucious.be | F8: BE0448692207 | G8: 2.359.957.342
A9: Pit & Pit | B9: Putten 27 2320 Hoogstraten | F9: BE0505805213
A10: Man & Brouw | B10: Aarschotsesteenweg 179 3012 Wilsele | C10: Sibren De Bast

Sheet Kostprijsberekening
A1: Overzicht grondstoffen
A3: Man & Brouw | B3: BE0778.696.105
A4: entrepotnr:
A6: Nr brouwsel | B6: Kostprijs grondstoffen | C6: Kostprijs verpakking | D6: Totale kostprijs
A7: 2023/001 | B7: =SUMIF(Granen!P$6:P$2000,A7,Granen!T$6:T$2000)+SUMIF(Gist!P$6:P$2000,A7,Gist!T$6:T$2000)+SUMIF(Hop!P$6:P$2000,A7,Hop!T$6:T$2000)+SUMIF(Toevoegingen!P$6:P$2000,A7,Toevoegingen!T$6:T$2000) -> 96.43625 | C7: =SUMIF(Verpakkingen!P$6:P$2000,A7,Verpakkingen!U$6:U$2000) -> 235.30171 | D7: =sum(B7,C7) -> 331.73796
A8: 2023/002 | B8: =SUMIF(Granen!P$6:P$2000,A8,Granen!T$6:T$2000)+SUMIF(Gist!P$6:P$2000,A8,Gist!T$6:T$2000)+SUMIF(Hop!P$6:P$2000,A8,Hop!T$6:T$2000)+SUMIF(Toevoegingen!P$6:P$2000,A8,Toevoegingen!T$6:T$2000) -> 62.1448 | C8: =SUMIF(Verpakkingen!P$6:P$2000,A8,Verpakkingen!U$6:U$2000) -> 84.83736 | D8: =sum(B8,C8) -> 146.98216
A9: 2023/003 | B9: =SUMIF(Granen!P$6:P$2000,A9,Granen!T$6:T$2000)+SUMIF(Gist!P$6:P$2000,A9,Gist!T$6:T$2000)+SUMIF(Hop!P$6:P$2000,A9,Hop!T$6:T$2000)+SUMIF(Toevoegingen!P$6:P$2000,A9,Toevoegingen!T$6:T$2000) -> 217.04693 | C9: =SUMIF(Verpakkingen!P$6:P$2000,A9,Verpakkingen!U$6:U$2000) -> 238.81317 | D9: =sum(B9,C9) -> 455.8601
A10: 2023/004 | B10: =SUMIF(Granen!P$6:P$2000,A10,Granen!T$6:T$2000)+SUMIF(Gist!P$6:P$2000,A10,Gist!T$6:T$2000)+SUMIF(Hop!P$6:P$2000,A10,Hop!T$6:T$2000)+SUMIF(Toevoegingen!P$6:P$2000,A10,Toevoegingen!T$6:T$2000) -> 241.38205 | C10: =SUMIF(Verpakkingen!P$6:P$2000,A10,Verpakkingen!U$6:U$2000) -> 265.25441 | D10: =sum(B10,C10) -> 506.63646
A11: 2023/005 | B11: =SUMIF(Granen!P$6:P$2000,A11,Granen!T$6:T$2000)+SUMIF(Gist!P$6:P$2000,A11,Gist!T$6:T$2000)+SUMIF(Hop!P$6:P$2000,A11,Hop!T$6:T$2000)+SUMIF(Toevoegingen!P$6:P$2000,A11,Toevoegingen!T$6:T$2000) -> 182.785 | C11: =SUMIF(Verpakkingen!P$6:P$2000,A11,Verpakkingen!U$6:U$2000) -> 232.11646 | D11: =sum(B11,C11) -> 414.90146
A12: 2023/006 | B12: =SUMIF(Granen!P$6:P$2000,A12,Granen!T$6:T$2000)+SUMIF(Gist!P$6:P$2000,A12,Gist!T$6:T$2000)+SUMIF(Hop!P$6:P$2000,A12,Hop!T$6:T$2000)+SUMIF(Toevoegingen!P$6:P$2000,A12,Toevoegingen!T$6:T$2000) -> 97.7158 | C12: =SUMIF(Verpakkingen!P$6:P$2000,A12,Verpakkingen!U$6:U$2000) -> 0 | D12: =sum(B12,C12) -> 97.7158
A13: 2023/007 | B13: =SUMIF(Granen!P$6:P$2000,A13,Granen!T$6:T$2000)+SUMIF(Gist!P$6:P$2000,A13,Gist!T$6:T$2000)+SUMIF(Hop!P$6:P$2000,A13,Hop!T$6:T$2000)+SUMIF(Toevoegingen!P$6:P$2000,A13,Toevoegingen!T$6:T$2000) -> 72.558 | C13: =SUMIF(Verpakkingen!P$6:P$2000,A13,Verpakkingen!U$6:U$2000) -> 191.80779 | D13: =sum(B13,C13) -> 264.36579
A14: 2023/008 | B14: =SUMIF(Granen!P$6:P$2000,A14,Granen!T$6:T$2000)+SUMIF(Gist!P$6:P$2000,A14,Gist!T$6:T$2000)+SUMIF(Hop!P$6:P$2000,A14,Hop!T$6:T$2000)+SUMIF(Toevoegingen!P$6:P$2000,A14,Toevoegingen!T$6:T$2000) -> 276.052 | C14: =SUMIF(Verpakkingen!P$6:P$2000,A14,Verpakkingen!U$6:U$2000) -> 219.54107 | D14: =sum(B14,C14) -> 495.59307
A15: 2023/009 | B15: =SUMIF(Granen!P$6:P$2000,A15,Granen!T$6:T$2000)+SUMIF(Gist!P$6:P$2000,A15,Gist!T$6:T$2000)+SUMIF(Hop!P$6:P$2000,A15,Hop!T$6:T$2000)+SUMIF(Toevoegingen!P$6:P$2000,A15,Toevoegingen!T$6:T$2000) -> 72.57025 | C15: =SUMIF(Verpakkingen!P$6:P$2000,A15,Verpakkingen!U$6:U$2000) -> 228.085 | D15: =sum(B15,C15) -> 300.65525
A16: 2023/010 | B16: =SUMIF(Granen!P$6:P$2000,A16,Granen!T$6:T$2000)+SUMIF(Gist!P$6:P$2000,A16,Gist!T$6:T$2000)+SUMIF(Hop!P$6:P$2000,A16,Hop!T$6:T$2000)+SUMIF(Toevoegingen!P$6:P$2000,A16,Toevoegingen!T$6:T$2000) -> 0 | C16: =SUMIF(Verpakkingen!P$6:P$2000,A16,Verpakkingen!U$6:U$2000) -> 188.46554 | D16: =sum(B16,C16) -> 188.46554
A17: 2023/011 | B17: =SUMIF(Granen!P$6:P$2000,A17,Granen!T$6:T$2000)+SUMIF(Gist!P$6:P$2000,A17,Gist!T$6:T$2000)+SUMIF(Hop!P$6:P$2000,A17,Hop!T$6:T$2000)+SUMIF(Toevoegingen!P$6:P$2000,A17,Toevoegingen!T$6:T$2000) -> 169.66705 | C17: =SUMIF(Verpakkingen!P$6:P$2000,A17,Verpakkingen!U$6:U$2000) -> 159.76382 | D17: =sum(B17,C17) -> 329.43087
A18: 2023/012 | B18: =SUMIF(Granen!P$6:P$2000,A18,Granen!T$6:T$2000)+SUMIF(Gist!P$6:P$2000,A18,Gist!T$6:T$2000)+SUMIF(Hop!P$6:P$2000,A18,Hop!T$6:T$2000)+SUMIF(Toevoegingen!P$6:P$2000,A18,Toevoegingen!T$6:T$2000) -> 127.894 | C18: =SUMIF(Verpakkingen!P$6:P$2000,A18,Verpakkingen!U$6:U$2000) -> 192.22588 | D18: =sum(B18,C18) -> 320.11988
... A44: 2025/014 | B44: =SUMIF(Granen!P$6:P$2000,A44,Granen!T$6:T$2000)+SUMIF(Gist!P$6:P$2000,A44,Gist!T$6:T$2000)+SUMIF(Hop!P$6:P$2000,A44,Hop!T$6:T$2000)+SUMIF(Toevoegingen!P$6:P$2000,A44,Toevoegingen!T$6:T$2000) -> 0 | C44: =SUMIF(Verpakkingen!P$6:P$2000,A44,Verpakkingen!U$6:U$2000) -> 0 | D44: =sum(B44,C44) -> 0
B45: =SUMIF(Granen!P$6:P$2000,A45,Granen!T$6:T$2000)+SUMIF(Gist!P$6:P$2000,A45,Gist!T$6:T$2000)+SUMIF(Hop!P$6:P$2000,A45,Hop!T$6:T$2000)+SUMIF(Toevoegingen!P$6:P$2000,A45,Toevoegingen!T$6:T$2000) -> 0 | C45: =SUMIF(Verpakkingen!P$6:P$2000,A45,Verpakkingen!U$6:U$2000) -> 0 | D45: =sum(B45,C45) -> 0
B46: =SUMIF(Granen!P$6:P$2000,A46,Granen!T$6:T$2000)+SUMIF(Gist!P$6:P$2000,A46,Gist!T$6:T$2000)+SUMIF(Hop!P$6:P$2000,A46,Hop!T$6:T$2000)+SUMIF(Toevoegingen!P$6:P$2000,A46,Toevoegingen!T$6:T$2000) -> 0 | C46: =SUMIF(Verpakkingen!P$6:P$2000,A46,Verpakkingen!U$6:U$2000) -> 0 | D46: =sum(B46,C46) -> 0
B47: =SUMIF(Granen!P$6:P$2000,A47,Granen!T$6:T$2000)+SUMIF(Gist!P$6:P$2000,A47,Gist!T$6:T$2000)+SUMIF(Hop!P$6:P$2000,A47,Hop!T$6:T$2000)+SUMIF(Toevoegingen!P$6:P$2000,A47,Toevoegingen!T$6:T$2000) -> 0 | C47: =SUMIF(Verpakkingen!P$6:P$2000,A47,Verpakkingen!U$6:U$2000) -> 0 | D47: =sum(B47,C47) -> 0
B48: =SUMIF(Granen!P$6:P$2000,A48,Granen!T$6:T$2000)+SUMIF(Gist!P$6:P$2000,A48,Gist!T$6:T$2000)+SUMIF(Hop!P$6:P$2000,A48,Hop!T$6:T$2000)+SUMIF(Toevoegingen!P$6:P$2000,A48,Toevoegingen!T$6:T$2000) -> 0 | C48: =SUMIF(Verpakkingen!P$6:P$2000,A48,Verpakkingen!U$6:U$2000) -> 0 | D48: =sum(B48,C48) -> 0
B49: =SUMIF(Granen!P$6:P$2000,A49,Granen!T$6:T$2000)+SUMIF(Gist!P$6:P$2000,A49,Gist!T$6:T$2000)+SUMIF(Hop!P$6:P$2000,A49,Hop!T$6:T$2000)+SUMIF(Toevoegingen!P$6:P$2000,A49,Toevoegingen!T$6:T$2000) -> 0 | C49: =SUMIF(Verpakkingen!P$6:P$2000,A49,Verpakkingen!U$6:U$2000) -> 0 | D49: =sum(B49,C49) -> 0
B50: =SUMIF(Granen!P$6:P$2000,A50,Granen!T$6:T$2000)+SUMIF(Gist!P$6:P$2000,A50,Gist!T$6:T$2000)+SUMIF(Hop!P$6:P$2000,A50,Hop!T$6:T$2000)+SUMIF(Toevoegingen!P$6:P$2000,A50,Toevoegingen!T$6:T$2000) -> 0 | C50: =SUMIF(Verpakkingen!P$6:P$2000,A50,Verpakkingen!U$6:U$2000) -> 0 | D50: =sum(B50,C50) -> 0
B51: =SUMIF(Granen!P$6:P$2000,A51,Granen!T$6:T$2000)+SUMIF(Gist!P$6:P$2000,A51,Gist!T$6:T$2000)+SUMIF(Hop!P$6:P$2000,A51,Hop!T$6:T$2000)+SUMIF(Toevoegingen!P$6:P$2000,A51,Toevoegingen!T$6:T$2000) -> 0 | C51: =SUMIF(Verpakkingen!P$6:P$2000,A51,Verpakkingen!U$6:U$2000) -> 0 | D51: =sum(B51,C51) -> 0
B52: =SUMIF(Granen!P$6:P$2000,A52,Granen!T$6:T$2000)+SUMIF(Gist!P$6:P$2000,A52,Gist!T$6:T$2000)+SUMIF(Hop!P$6:P$2000,A52,Hop!T$6:T$2000)+SUMIF(Toevoegingen!P$6:P$2000,A52,Toevoegingen!T$6:T$2000) -> 0 | C52: =SUMIF(Verpakkingen!P$6:P$2000,A52,Verpakkingen!U$6:U$2000) -> 0 | D52: =sum(B52,C52) -> 0
B53: =SUMIF(Granen!P$6:P$2000,A53,Granen!T$6:T$2000)+SUMIF(Gist!P$6:P$2000,A53,Gist!T$6:T$2000)+SUMIF(Hop!P$6:P$2000,A53,Hop!T$6:T$2000)+SUMIF(Toevoegingen!P$6:P$2000,A53,Toevoegingen!T$6:T$2000) -> 0 | C53: =SUMIF(Verpakkingen!P$6:P$2000,A53,Verpakkingen!U$6:U$2000) -> 0 | D53: =sum(B53,C53) -> 0
B54: =SUMIF(Granen!P$6:P$2000,A54,Granen!T$6:T$2000)+SUMIF(Gist!P$6:P$2000,A54,Gist!T$6:T$2000)+SUMIF(Hop!P$6:P$2000,A54,Hop!T$6:T$2000)+SUMIF(Toevoegingen!P$6:P$2000,A54,Toevoegingen!T$6:T$2000) -> 0 | C54: =SUMIF(Verpakkingen!P$6:P$2000,A54,Verpakkingen!U$6:U$2000) -> 0 | D54: =sum(B54,C54) -> 0
B55: =SUMIF(Granen!P$6:P$2000,A55,Granen!T$6:T$2000)+SUMIF(Gist!P$6:P$2000,A55,Gist!T$6:T$2000)+SUMIF(Hop!P$6:P$2000,A55,Hop!T$6:T$2000)+SUMIF(Toevoegingen!P$6:P$2000,A55,Toevoegingen!T$6:T$2000) -> 0 | C55: =SUMIF(Verpakkingen!P$6:P$2000,A55,Verpakkingen!U$6:U$2000) -> 0 | D55: =sum(B55,C55) -> 0
B56: =SUMIF(Granen!P$6:P$2000,A56,Granen!T$6:T$2000)+SUMIF(Gist!P$6:P$2000,A56,Gist!T$6:T$2000)+SUMIF(Hop!P$6:P$2000,A56,Hop!T$6:T$2000)+SUMIF(Toevoegingen!P$6:P$2000,A56,Toevoegingen!T$6:T$2000) -> 0 | C56: =SUMIF(Verpakkingen!P$6:P$2000,A56,Verpakkingen!U$6:U$2000) -> 0 | D56: =sum(B56,C56) -> 0
... B100: =SUMIF(Granen!P$6:P$2000,A100,Granen!T$6:T$2000)+SUMIF(Gist!P$6:P$2000,A100,Gist!T$6:T$2000)+SUMIF(Hop!P$6:P$2000,A100,Hop!T$6:T$2000)+SUMIF(Toevoegingen!P$6:P$2000,A100,Toevoegingen!T$6:T$2000) -> 0 | C100: =SUMIF(Verpakkingen!P$6:P$2000,A100,Verpakkingen!U$6:U$2000) -> 0 | D100: =sum(B100,C100) -> 0

Sheet Granen
A1: Granen
A3: IN | P3: OUT
A5: Nr inslagbon | B5: Factuur nummer | C5: Naam ontvanger | D5: Datum | E5: Leverancier | F5: Fabricant | G5: Soort | H5: Lot | I5: Houdbaar tot | J5: Hoeveelheid [kg] | K5: Kostprijs [€] | L5: Afwijking? | M5: Actie? | N5: Opmerkingen | P5: Nr Brouwsel | Q5: Datum | R5: Soort | S5: Hoeveelheid [kg] | T5: Kostprijs [€] | U5: Lot
B6: A2023007 | C6: Tom | D6: 45009 | E6: Hof Ten Dormaal | G6: Pilsmout | H6: 23-004 | I6: 45658 | J6: 50 | K6: =26*1.21 -> 31.46 | P6: 2023/001 | Q6: 45015 | R6: Pilsmout | S6: 40 | T6: =IF(ISBLANK(U6),"",VLOOKUP($U6,$H$6:$K$2000,4,FALSE)/VLOOKUP(U6,$H$6:$K$2000,3,FALSE)*$S6) -> 25.168 | U6: 23-004
B7: A2023007 | C7: Tom | D7: 45009 | E7: Hof Ten Dormaal | G7: Tarwemout | H7: 23-011 | I7: 45689 | J7: 25 | K7: 25.65 | P7: 2023/002 | Q7: 45015 | R7: Pilsmout | S7: 10 | T7: =IF(ISBLANK(U7),"",VLOOKUP($U7,$H$6:$K$2000,4,FALSE)/VLOOKUP(U7,$H$6:$K$2000,3,FALSE)*$S7) -> 6.292 | U7: 23-004
B8: A2023007 | C8: Tom | D8: 45009 | E8: Hof Ten Dormaal | G8: Tarwemout | H8: 23-008 | I8: 45689 | J8: 25 | K8: 25.65 | P8: 2023/001 | Q8: 45015 | R8: Tarwemout | S8: 20 | T8: =IF(ISBLANK(U8),"",VLOOKUP($U8,$H$6:$K$2000,4,FALSE)/VLOOKUP(U8,$H$6:$K$2000,3,FALSE)*$S8) -> 20.52 | U8: 23-011
B9: A2023007 | C9: Tom | D9: 45009 | E9: Hof Ten Dormaal | G9: Munich | H9: 22-086 | I9: 45505 | J9: 75 | K9: 78.23 | P9: 2023/002 | Q9: 45015 | R9: Tarwemout | S9: 5 | T9: =IF(ISBLANK(U9),"",VLOOKUP($U9,$H$6:$K$2000,4,FALSE)/VLOOKUP(U9,$H$6:$K$2000,3,FALSE)*$S9) -> 5.13 | U9: 23-011
A10: 372012518 | B10: A2023005 | C10: Sibren | D10: 45013 | E10: Brouwland | F10: Weyermann | G10: CaraAroma | H10: Y017 | I10: 45552 | J10: 25 | K10: 40.55 | L10: Verpakking | M10: Rechtzetting | N10: verpakking gescheurd | P10: 2023/003 | Q10: 45020 | R10: Tarwemout | S10: 9.1 | T10: =IF(ISBLANK(U10),"",VLOOKUP($U10,$H$6:$K$2000,4,FALSE)/VLOOKUP(U10,$H$6:$K$2000,3,FALSE)*$S10) -> 9.3366 | U10: 23-008
B11: A2023007 | C11: Tom | D11: 45009 | E11: Hof Ten Dormaal | G11: Witte Haver | H11: 22-016 | I11: 45352 | J11: 25 | K11: 12.72 | P11: 2023/003 | Q11: 45020 | R11: Munich | S11: 50 | T11: =IF(ISBLANK(U11),"",VLOOKUP($U11,$H$6:$K$2000,4,FALSE)/VLOOKUP(U11,$H$6:$K$2000,3,FALSE)*$S11) -> 52.153333 | U11: 22-086
A12: 372012518 | B12: A2023005 | C12: Sibren | D12: 45013 | E12: Brouwland | F12: Castle Malting | G12: CaraGold | H12: M221200246 | I12: 45645 | J12: 25 | K12: 33.95 | P12: 2023/003 | Q12: 45020 | R12: CaraAroma | S12: 12.5 | T12: =IF(ISBLANK(U12),"",VLOOKUP($U12,$H$6:$K$2000,4,FALSE)/VLOOKUP(U12,$H$6:$K$2000,3,FALSE)*$S12) -> 20.275 | U12: Y017
A13: 372012518 | B13: A2023005 | C13: Sibren | D13: 45013 | E13: Brouwland | F13: Viking | G13: CaraBody | H13: BA/2022-01-27/cb | I13: 45538 | J13: 5 | K13: 13.35 | P13: 2023/003 | Q13: 45020 | R13: Witte Haver | S13: 5 | T13: =IF(ISBLANK(U13),"",VLOOKUP($U13,$H$6:$K$2000,4,FALSE)/VLOOKUP(U13,$H$6:$K$2000,3,FALSE)*$S13) -> 2.544 | U13: 22-016
A14: 372012518 | B14: A2023005 | C14: Sibren | D14: 45013 | E14: Brouwland | G14: Biscuit | H14: BA/M221000179 | I14: 45452 | J14: 5 | K14: 11.35 | P14: 2023/003 | Q14: 45020 | R14: CaraGold | S14: 12 | T14: =IF(ISBLANK(U14),"",VLOOKUP($U14,$H$6:$K$2000,4,FALSE)/VLOOKUP(U14,$H$6:$K$2000,3,FALSE)*$S14) -> 16.296 | U14: M221200246
A15: 372012518 | B15: A2023005 | C15: Sibren | D15: 45013 | E15: Brouwland | G15: Biscuit | H15: BA/M230100326 | I15: 45545 | J15: 1 | K15: 6 | P15: 2023/001 | Q15: 45015 | R15: CaraBody | S15: 4 | T15: =IF(ISBLANK(U15),"",VLOOKUP($U15,$H$6:$K$2000,4,FALSE)/VLOOKUP(U15,$H$6:$K$2000,3,FALSE)*$S15) -> 10.68 | U15: BA/2022-01-27/cb
A16: 372012518 | B16: A2023005 | C16: Sibren | D16: 45013 | E16: Brouwland | G16: Chocolate Dark | H16: BA/20221010/C212 | I16: 45521 | J16: 5 | K16: 14.62 | P16: 2023/002 | Q16: 45015 | R16: CaraBody | S16: 1 | T16: =IF(ISBLANK(U16),"",VLOOKUP($U16,$H$6:$K$2000,4,FALSE)/VLOOKUP(U16,$H$6:$K$2000,3,FALSE)*$S16) -> 2.67 | U16: BA/2022-01-27/cb
A17: 372012518 | B17: A2023005 | C17: Sibren | D17: 45013 | E17: Brouwland | G17: Chocolate Dark | H17: BA/20221010/CZ12 | I17: 45528 | J17: 1 | K17: 3.68 | P17: 2023/003 | Q17: 45020 | R17: Biscuit | S17: 5 | T17: =IF(ISBLANK(U17),"",VLOOKUP($U17,$H$6:$K$2000,4,FALSE)/VLOOKUP(U17,$H$6:$K$2000,3,FALSE)*$S17) -> 11.35 | U17: BA/M221000179
B18: A2023014 | C18: Tom | D18: 45083 | E18: Hof Ten Dormaal | G18: Pilsmout | H18: 22-120 | I18: 45536 | J18: 50 | K18: 48.76 | P18: 2023/003 | Q18: 45020 | R18: Chocolate Dark | S18: 5 | T18: =IF(ISBLANK(U18),"",VLOOKUP($U18,$H$6:$K$2000,4,FALSE)/VLOOKUP(U18,$H$6:$K$2000,3,FALSE)*$S18) -> 14.62 | U18: BA/20221010/C212
B19: a2023014 | C19: Tom | D19: 45083 | E19: Hof Ten Dormaal | G19: Tarwe | H19: 22-055 | J19: 25 | K19: 12.72 | P19: 2023/004 | Q19: 45085 | R19: Tarwe | S19: 25 | T19: =IF(ISBLANK(U19),"",VLOOKUP($U19,$H$6:$K$2000,4,FALSE)/VLOOKUP(U19,$H$6:$K$2000,3,FALSE)*$S19) -> 12.72 | U19: 22-055
B20: a2023021 | C20: Sibren | D20: 45104 | E20: Hof Ten Dormaal | G20: Pilsmout | H20: 23-031 | I20: 45809 | J20: 50 | K20: 48.76 | P20: 2023/004 | Q20: 45085 | R20: Pilsmout | S20: 40 | T20: =IF(ISBLANK(U20),"",VLOOKUP($U20,$H$6:$K$2000,4,FALSE)/VLOOKUP(U20,$H$6:$K$2000,3,FALSE)*$S20) -> 39.008 | U20: 22-120
C21: Sibren | D21: 45134 | E21: Hof ten Dormaal | G21: Pilsmout | H21: 22-120 | I21: 45536 | J21: 25 | K21: 24.38 | P21: 2023/005 | Q21: 45113 | R21: Pilsmout | S21: 50 | T21: =IF(ISBLANK(U21),"",VLOOKUP($U21,$H$6:$K$2000,4,FALSE)/VLOOKUP(U21,$H$6:$K$2000,3,FALSE)*$S21) -> 48.76 | U21: 23-031
C22: Sibren | D22: 45134 | E22: Hof ten Dormaal | G22: Tarwe | H22: 22-116 | I22: 45536 | J22: 25 | K22: 10.81 | P22: 2023/005 | Q22: 45113 | R22: Chocolate Dark | S22: 1 | T22: =IF(ISBLANK(U22),"",VLOOKUP($U22,$H$6:$K$2000,4,FALSE)/VLOOKUP(U22,$H$6:$K$2000,3,FALSE)*$S22) -> 3.68 | U22: BA/20221010/CZ12
B23: / | C23: Sibren | D23: 45136 | E23: Bakkerij Apers | G23: Oud brood | H23: / | I23: / | J23: 10 | K23: 0 | P23: 2023/005 | Q23: 45113 | R23: Tarwemout | S23: 5 | T23: =IF(ISBLANK(U23),"",VLOOKUP($U23,$H$6:$K$2000,4,FALSE)/VLOOKUP(U23,$H$6:$K$2000,3,FALSE)*$S23) -> 5.13 | U23: 23-008
B24: A2023045 | D24: 45162 | E24: Hof ten Dormaal | G24: Pilsmout | H24: 23-031 | I24: 45778 | J24: 75 | K24: 73.14 | P24: 2023/005 | Q24: 45113 | R24: CaraAroma | S24: 12.5 | T24: =IF(ISBLANK(U24),"",VLOOKUP($U24,$H$6:$K$2000,4,FALSE)/VLOOKUP(U24,$H$6:$K$2000,3,FALSE)*$S24) -> 20.275 | U24: Y017
B25: A2023045 | D25: 45162 | E25: Hof ten Dormaal | G25: Tarwemout | H25: 23-011 | J25: 25 | K25: 25.65 | P25: 2023/005 | Q25: 45113 | R25: CaraGold | S25: 13 | T25: =IF(ISBLANK(U25),"",VLOOKUP($U25,$H$6:$K$2000,4,FALSE)/VLOOKUP(U25,$H$6:$K$2000,3,FALSE)*$S25) -> 17.654 | U25: M221200246
B26: A2023045 | D26: 45162 | E26: Hof ten Dormaal | G26: Tarwe | H26: 22-116 | I26: 45536 | J26: 25 | K26: 10.81 | P26: 2023/005 | Q26: 45113 | R26: Biscuit | S26: 1 | T26: =IF(ISBLANK(U26),"",VLOOKUP($U26,$H$6:$K$2000,4,FALSE)/VLOOKUP(U26,$H$6:$K$2000,3,FALSE)*$S26) -> 6 | U26: BA/M230100326
C27: Sibren | D27: 45184 | E27: Brouwland | G27: CaraGold | H27: BA-M230100398 | I27: 45627 | J27: 5 | K27: 10.1 | P27: - | Q27: - | R27: Witte Haver | S27: 20 | T27: =IF(ISBLANK(U27),"",VLOOKUP($U27,$H$6:$K$2000,4,FALSE)/VLOOKUP(U27,$H$6:$K$2000,3,FALSE)*$S27) -> 10.176 | U27: 22-016 | V27: Uit stock gehaald na QC
D28: 45224 | E28: Hof ten Dormaal | G28: Pilsmout | H28: 23-041 | I28: 45870 | J28: 50 | K28: =2*24.38 -> 48.76 | P28: 2023/006 | Q28: 45141 | R28: Pilsmout | S28: 35 | T28: =IF(ISBLANK(U28),"",VLOOKUP($U28,$H$6:$K$2000,4,FALSE)/VLOOKUP(U28,$H$6:$K$2000,3,FALSE)*$S28) -> 34.132 | U28: 22-120
D29: 45224 | E29: Hof ten Dormaal | G29: Tarwe | H29: 23-042 | I29: 45870 | J29: 25 | K29: 12.72 | P29: 2023/006 | Q29: 45141 | R29: Tarwe | S29: 20 | T29: =IF(ISBLANK(U29),"",VLOOKUP($U29,$H$6:$K$2000,4,FALSE)/VLOOKUP(U29,$H$6:$K$2000,3,FALSE)*$S29) -> 8.648 | U29: 22-116
C30: Sibren | D30: 45258 | E30: Hof ten Dormaal | G30: Pilsmout | H30: 23-041 | I30: 45870 | J30: 75 | K30: =3*24.38 -> 73.14 | P30: 2023/006 | Q30: 45141 | R30: Tarwemout | S30: 10 | T30: =IF(ISBLANK(U30),"",VLOOKUP($U30,$H$6:$K$2000,4,FALSE)/VLOOKUP(U30,$H$6:$K$2000,3,FALSE)*$S30) -> 10.26 | U30: 23-008
D31: 45252 | E31: Brouwland | G31: Biscuit | H31: BAM230700063 | I31: 45717 | J31: 10 | K31: 20.59 | P31: 2023/006 | Q31: 45141 | R31: Oud brood | S31: 10 | T31: =IF(ISBLANK(U31),"",VLOOKUP($U31,$H$6:$K$2000,4,FALSE)/VLOOKUP(U31,$H$6:$K$2000,3,FALSE)*$S31) -> 0 | U31: /
D32: 45252 | E32: Brouwland | G32: Witte Haver | H32: 20240311 | I32: 45352 | J32: 15 | K32: 23.49 | P32: 2023/007 | Q32: 45169 | R32: Tarwe | S32: 20 | T32: =IF(ISBLANK(U32),"",VLOOKUP($U32,$H$6:$K$2000,4,FALSE)/VLOOKUP(U32,$H$6:$K$2000,3,FALSE)*$S32) -> 8.648 | U32: 22-116
D33: 45303 | E33: Brouwland | G33: Chocolate Dark | H33: BAZR070113198 | I33: 45792 | J33: 3 | K33: 7.75 | P33: 2023/007 | Q33: 45169 | R33: Pilsmout | S33: 50 | T33: =IF(ISBLANK(U33),"",VLOOKUP($U33,$H$6:$K$2000,4,FALSE)/VLOOKUP(U33,$H$6:$K$2000,3,FALSE)*$S33) -> 48.76 | U33: 23-031
D34: 45303 | E34: Brouwland | G34: CaraAroma | H34: BA-Y292 | I34: 45969 | J34: 10 | K34: 26.15 | P34: 2023/008 | Q34: 45204 | R34: CaraGold | S34: 5 | T34: =IF(ISBLANK(U34),"",VLOOKUP($U34,$H$6:$K$2000,4,FALSE)/VLOOKUP(U34,$H$6:$K$2000,3,FALSE)*$S34) -> 10.1 | U34: BA-M230100398
D35: 45303 | E35: Brouwland | G35: Biscuit | H35: BA-M230900019 | I35: 45801 | J35: 10 | K35: 20.6 | P35: 2023/008 | Q35: 45204 | R35: Pilsmout | S35: 25 | T35: =IF(ISBLANK(U35),"",VLOOKUP($U35,$H$6:$K$2000,4,FALSE)/VLOOKUP(U35,$H$6:$K$2000,3,FALSE)*$S35) -> 24.38 | U35: 23-031
D36: 45296 | E36: Hof ten Dormaal | G36: Pilsmout | H36: 22-120 | I36: 45536 | J36: 100 | K36: 96 | P36: 2023/008 | Q36: 45204 | R36: Tarwemout | S36: 25 | T36: =IF(ISBLANK(U36),"",VLOOKUP($U36,$H$6:$K$2000,4,FALSE)/VLOOKUP(U36,$H$6:$K$2000,3,FALSE)*$S36) -> 25.65 | U36: 23-011
D37: 45296 | E37: Hof ten Dormaal | G37: Tarwe | H37: 23-042 | I37: 45870 | J37: 25 | K37: 12.5 | P37: 2023/008 | Q37: 45204 | R37: Tarwe | S37: 5 | T37: =IF(ISBLANK(U37),"",VLOOKUP($U37,$H$6:$K$2000,4,FALSE)/VLOOKUP(U37,$H$6:$K$2000,3,FALSE)*$S37) -> 2.162 | U37: 22-116
D38: 45303 | E38: Brouwland | F38: Chateau | G38: Tarwemout | H38: M231000327 | I38: 45963 | J38: 25 | K38: 26.35 | P38: 2023/009 | Q38: 45231 | R38: Tarwe | S38: 25 | T38: =IF(ISBLANK(U38),"",VLOOKUP($U38,$H$6:$K$2000,4,FALSE)/VLOOKUP(U38,$H$6:$K$2000,3,FALSE)*$S38) -> 12.72 | U38: 23-042
D39: 45303 | E39: Brouwland | G39: Havervlokken | H39: 2402250 | I39: 46005 | J39: 25 | K39: 29.1 | P39: 2023/009 | Q39: 45231 | R39: Pilsmout | S39: 40 | T39: =IF(ISBLANK(U39),"",VLOOKUP($U39,$H$6:$K$2000,4,FALSE)/VLOOKUP(U39,$H$6:$K$2000,3,FALSE)*$S39) -> 39.008 | U39: 23-041
D40: 45303 | E40: Brouwland | F40: Weyermann | G40: CaraAmber | H40: Y264 | I40: 45737 | J40: 25 | K40: 36.65 | P40: 2023/011 | Q40: 45259 | R40: Pilsmout | S40: 64 | T40: =IF(ISBLANK(U40),"",VLOOKUP($U40,$H$6:$K$2000,4,FALSE)/VLOOKUP(U40,$H$6:$K$2000,3,FALSE)*$S40) -> 62.4128 | U40: 23-041
D41: 45287 | E41: Brouwland | G41: Caramel 30 | H41: BA-2023-05-04/90 | I41: 45801 | J41: 5 | K41: 10.6 | P41: 2023/011 | Q41: 45259 | R41: Tarwe | S41: 5 | T41: =IF(ISBLANK(U41),"",VLOOKUP($U41,$H$6:$K$2000,4,FALSE)/VLOOKUP(U41,$H$6:$K$2000,3,FALSE)*$S41) -> 2.544 | U41: 23-042
D42: 45336 | E42: Hof ten Dormaal | G42: Pilsmout | H42: 22-120 | I42: 45536 | J42: 125 | K42: =96/4*5 -> 120 | P42: 2023/011 | Q42: 45259 | R42: Biscuit | S42: 10 | T42: =IF(ISBLANK(U42),"",VLOOKUP($U42,$H$6:$K$2000,4,FALSE)/VLOOKUP(U42,$H$6:$K$2000,3,FALSE)*$S42) -> 20.59 | U42: BAM230700063
...

Sheet Gist
A1: Gist
A3: IN | P3: OUT
A5: Nr inslagbon | B5: Factuur nummer | C5: Naam ontvanger | D5: Datum | E5: Leverancier | F5: Fabricant | G5: Soort | H5: Lot | I5: Houdbaar tot | J5: Hoeveelheid [kg] | K5: Kostprijs [€] | L5: Afwijking? | M5: Actie? | N5: Opmerkingen | P5: Nr Brouwsel | Q5: Datum | R5: Soort | S5: Hoeveelheid [kg] | T5: Kostprijs [€] | U5: Lot
B6: A2023005 | C6: Sibren | D6: 45013 | E6: Brouwland | F6: Lallemand | G6: Verdant IPA | H6: 45806741027711X | I6: 45689 | J6: 0.055 | K6: =17.88*1.06 -> 18.9528 | P6: 2023/002 | Q6: 45015 | R6: Verdant IPA | S6: 0.055 | T6: =IF(ISBLANK(U6),"",VLOOKUP($U6,$H$6:$K$2000,4,FALSE)/VLOOKUP(U6,$H$6:$K$2000,3,FALSE)*$S6) -> 18.9528 | U6: 45806741027711X
B7: A2023005 | C7: Sibren | D7: 45013 | E7: Brouwland | F7: Fermentis | G7: LP652 | H7: 2203741590926 | I7: 45809 | J7: 0.1 | K7: =78.65*1.06 -> 83.369 | P7: 2023/001 | Q7: 45015 | R7: LP652 | S7: 0.025 | T7: =IF(ISBLANK(U7),"",VLOOKUP($U7,$H$6:$K$2000,4,FALSE)/VLOOKUP(U7,$H$6:$K$2000,3,FALSE)*$S7) -> 20.84225 | U7: 2203741590926
B8: / | C8: Sibren | D8: 45017 | E8: Coureur | F8: Fermentis | G8: S-04 | H8: 2000657 KB | I8: 45261 | J8: 0.2 | K8: 0 | P8: 2023/001 | Q8: 45018 | R8: S-04 | S8: 0.2 | T8: =IF(ISBLANK(U8),"",VLOOKUP($U8,$H$6:$K$2000,4,FALSE)/VLOOKUP(U8,$H$6:$K$2000,3,FALSE)*$S8) -> 0 | U8: 2000657 KB
B9: A2023012 | C9: Sibren | D9: 45076 | E9: Brouwland | F9: Fermentis | G9: WB-06 | H9: 262381 | I9: 04/25 | J9: 0.5 | K9: =1.06*68.06 -> 72.1436 | P9: 2023/004 | Q9: 45086 | R9: WB-06 | S9: 0.25 | T9: =IF(ISBLANK(U9),"",VLOOKUP($U9,$H$6:$K$2000,4,FALSE)/VLOOKUP(U9,$H$6:$K$2000,3,FALSE)*$S9) -> 36.0718 | U9: 262381
B10: A2023030 | C10: Sibren | D10: 45111 | E10: HVB | F10: Fermentis | G10: BE-256 | H10: 2200597 | I10: 45778 | J10: 0.5 | K10: =1.06*62 -> 65.72 | P10: 2023/004 | Q10: 45085 | R10: LP652 | S10: 0.025 | T10: =IF(ISBLANK(U10),"",VLOOKUP($U10,$H$6:$K$2000,4,FALSE)/VLOOKUP(U10,$H$6:$K$2000,3,FALSE)*$S10) -> 20.84225 | U10: 2203741590926
C11: Sibren | D11: 45337 | E11: Brouwland | F11: Fermentis | G11: LP652 | H11: 2203741590926 | I11: 45809 | J11: 0.1 | K11: =78.65*1.06 -> 83.369 | P11: 2023/005 | Q11: 45114 | R11: BE-256 | S11: 0.25 | T11: =IF(ISBLANK(U11),"",VLOOKUP($U11,$H$6:$K$2000,4,FALSE)/VLOOKUP(U11,$H$6:$K$2000,3,FALSE)*$S11) -> 32.86 | U11: 2200597
C12: Sibren | D12: 45295 | E12: De coureur | F12: Fermentis | G12: S-33 | H12: AJH7200848 | I12: 45809 | J12: 0.4 | K12: 0 | N12: rest van de coureur | P12: 2023/006 | Q12: 45141 | R12: WB-06 | S12: 0.25 | T12: =IF(ISBLANK(U12),"",VLOOKUP($U12,$H$6:$K$2000,4,FALSE)/VLOOKUP(U12,$H$6:$K$2000,3,FALSE)*$S12) -> 36.0718 | U12: 262381
C13: Sibren | D13: 45295 | E13: De coureur | F13: Fermentis | G13: US-05 | H13: AJH152201209 | I13: 45809 | J13: 0.2 | K13: 0 | N13: rest van de coureur | P13: 2023/009 | Q13: 45231 | R13: LP652 | S13: 0.025 | T13: =IF(ISBLANK(U13),"",VLOOKUP($U13,$H$6:$K$2000,4,FALSE)/VLOOKUP(U13,$H$6:$K$2000,3,FALSE)*$S13) -> 20.84225 | U13: 2203741590926
C14: Sibren | D14: 45420 | E14: De coureur | F14: Fermentis | G14: S-04 | H14: AJH52300276 | I14: 46081 | J14: 0.5 | K14: =44*1.06 -> 46.64 | P14: 2023/011 | Q14: 45259 | R14: BE-256 | S14: 0.25 | T14: =IF(ISBLANK(U14),"",VLOOKUP($U14,$H$6:$K$2000,4,FALSE)/VLOOKUP(U14,$H$6:$K$2000,3,FALSE)*$S14) -> 32.86 | U14: 2200597
C15: Sibren | D15: 45420 | E15: De coureur | F15: Lallemand | G15: Voss Kveik | H15: 45708840430611V | I15: 45900 | J15: 0.5 | K15: =87*1.06 -> 92.22 | P15: 2024/001 | Q15: 45315 | R15: LP652 | S15: 0.025 | T15: =IF(ISBLANK(U15),"",VLOOKUP($U15,$H$6:$K$2000,4,FALSE)/VLOOKUP(U15,$H$6:$K$2000,3,FALSE)*$S15) -> 20.84225 | U15: 2203741590926
C16: Sibren | D16: 45483 | E16: Luvi Fermente | G16: Aspergillus Luchuensis | H16: 46256 | I16: 45627 | J16: 0.003 | K16: 26.23 | P16: 2024/003 | Q16: 45378 | R16: LP652 | S16: 0.025 | T16: =IF(ISBLANK(U16),"",VLOOKUP($U16,$H$6:$K$2000,4,FALSE)/VLOOKUP(U16,$H$6:$K$2000,3,FALSE)*$S16) -> 20.84225 | U16: 2203741590926
D17: 45609 | E17: Brouwland | F17: Fermentis | G17: US-05 | H17: AJ H5 2301006 | I17: 46266 | J17: 0.5 | K17: =51.9*1.21 -> 62.799 | P17: 2024/003 | Q17: 45380 | R17: S-33 | S17: 0.2 | T17: =IF(ISBLANK(U17),"",VLOOKUP($U17,$H$6:$K$2000,4,FALSE)/VLOOKUP(U17,$H$6:$K$2000,3,FALSE)*$S17) -> 0 | U17: AJH7200848
