Workbook
Name OG: 'XXX - cola sour'!$B$9
Name Volume: #REF!
Name OG: 'XXX - Parelende Pippa'!$B$9
Name ABV: '002 - Exquise Elise'!$B$11
Name FG: '008 - Pastry Orangette'!$B$10
Name Attenuation: 'XXX - Parelende Pippa'!$B$7
Name Volume: 'XXX - Parelende Pippa'!$B$5
Name Volume: '004 - Elegante Elodie'!$B$5
Name Brouwefficientie: #REF!
Name FG: 'XXX - Parelende Pippa'!$B$10
Name FG: '003 - Mystieke Margarita'!$B$10
Name OG: '003 - Mystieke Margarita'!$B$9
Name kgperpound: Data!$E$3
Name ABV: '001 - Heisse Hetty'!$B$11
Name ABV: '008 - Pastry Orangette'!$B$11
Name ABV: 'XXX - Parelende Pippa'!$B$11
Name FG: '002 - Exquise Elise'!$B$10
Name Plato: '001 - Heisse Hetty'!$B$12
Name Brouwefficientie: '008 - Pastry Orangette'!$B$8
Name Attenuation: '003 - Mystieke Margarita'!$B$7
Name Volume: '003 - Mystieke Margarita'!$B$5
Name OG: '008 - Pastry Orangette'!$B$9
Name Plato: 'XXX - Parelende Pippa'!$B$12
Name Attenuation: 'XXX - cola sour'!$B$7
Name lpergallon: Data!$E$2
Name Plato: #REF!
Name Attenuation: '004 - Elegante Elodie'!$B$7
Name FG: '001 - Heisse Hetty'!$B$10
Name FG: #REF!
Name Volume: '008 - Pastry Orangette'!$B$5
Name Plato: 'XXX - cola sour'!$B$12
Name Attenuation: '002 - Exquise Elise'!$B$7
Name Plato: '008 - Pastry Orangette'!$B$12
Name Brouwefficientie: '001 - Heisse Hetty'!$B$8
Name Brouwefficientie: 'XXX - cola sour'!$B$8
Name Attenuation: #REF!
Name FG: 'XXX - cola sour'!$B$10
Name ABV: '004 - Elegante Elodie'!$B$11
Name ABV: #REF!
Name Plato: '002 - Exquise Elise'!$B$12
Name Brouwefficientie: '002 - Exquise Elise'!$B$8
Name Attenuation: '008 - Pastry Orangette'!$B$7
Name OG: '002 - Exquise Elise'!$B$9
Name OG: '004 - Elegante Elodie'!$B$9
Name Volume: '002 - Exquise Elise'!$B$5
Name FG: '004 - Elegante Elodie'!$B$10
Name ozpergram: Data!$E$4
Name OG: #REF!
Name Brouwefficientie: '003 - Mystieke Margarita'!$B$8
Name Volume: 'XXX - cola sour'!$B$5
Name Attenuation: '001 - Heisse Hetty'!$B$7
Name OG: '001 - Heisse Hetty'!$B$9
Name ABV: '003 - Mystieke Margarita'!$B$11
Name Plato: '003 - Mystieke Margarita'!$B$12
Name ABV: 'XXX - cola sour'!$B$11
Name Volume: '001 - Heisse Hetty'!$B$5
Name Brouwefficientie: '004 - Elegante Elodie'!$B$8
Name Plato: '004 - Elegante Elodie'!$B$12
Name Brouwefficientie: 'XXX - Parelende Pippa'!$B$8

Sheet Overzicht
A1: T
A3: Brouwerij | B3: Man & Brouw
B4: BE0778.696.105
A6: Overzicht | D6: Verwacht | H6: Gemeten
A7: Fiche nummer | B7: Naam | C7: Sheet name | D7: OG | E7: FG | F7: ABV | G7: Plato | H7: OG | I7: FG | J7: ABV | K7: Plato | L7: Brouwefficientie
A8: 2026/001 | B8: Heisse Hetty | C8: =concat(MID(A8,6,3),concat(" - ", B8)) -> 001 - Heisse Hetty | D8: =iferror(INDIRECT(CONCATENATE(C8,"!","$G$5")),"") -> 1.0478662 | E8: =iferror(INDIRECT(CONCATENATE(C8,"!","$G$6")),"") -> 1.0095732 | F8: =iferror(INDIRECT(CONCATENATE(C8,"!","$G$7")),"") -> 0.050259526 | G8: =iferror(INDIRECT(CONCATENATE(C8,"!","$G$8")),"") -> 11.878125 | H8: =iferror(INDIRECT(CONCATENATE(C8,"!","$K$5")),"") | I8: =iferror(INDIRECT(CONCATENATE(C8,"!","$K$6")),"") | J8: =iferror(INDIRECT(CONCATENATE(C8,"!","$K$7")),"") | K8: =iferror(INDIRECT(CONCATENATE(C8,"!","$K$8")),"") | L8: =iferror(INDIRECT(CONCATENATE(C8,"!","$K$9")),"") -> 0
A9: 2026/002 | B9: Exquise Elise | C9: =concat(MID(A9,6,3),concat(" - ", B9)) -> 002 - Exquise Elise | D9: =iferror(INDIRECT(CONCATENATE(C9,"!","$G$5")),"") -> 1.0493378 | E9: =iferror(INDIRECT(CONCATENATE(C9,"!","$G$6")),"") -> 1.0024669 | F9: =iferror(INDIRECT(CONCATENATE(C9,"!","$G$7")),"") -> 0.061518123 | G9: =iferror(INDIRECT(CONCATENATE(C9,"!","$G$8")),"") -> 12.228125 | H9: =iferror(INDIRECT(CONCATENATE(C9,"!","$K$5")),"") | I9: =iferror(INDIRECT(CONCATENATE(C9,"!","$K$6")),"") | J9: =iferror(INDIRECT(CONCATENATE(C9,"!","$K$7")),"") | K9: =iferror(INDIRECT(CONCATENATE(C9,"!","$K$8")),"") | L9: =iferror(INDIRECT(CONCATENATE(C9,"!","$K$9")),"") -> 0
A10: 2026/003 | C10: =concat(MID(A10,6,3),concat(" - ", B10)) -> 003 - | D10: =iferror(INDIRECT(CONCATENATE(C10,"!","$G$5")),"") | E10: =iferror(INDIRECT(CONCATENATE(C10,"!","$G$6")),"") | F10: =iferror(INDIRECT(CONCATENATE(C10,"!","$G$7")),"") | G10: =iferror(INDIRECT(CONCATENATE(C10,"!","$G$8")),"") | H10: =iferror(INDIRECT(CONCATENATE(C10,"!","$K$5")),"") | I10: =iferror(INDIRECT(CONCATENATE(C10,"!","$K$6")),"") | J10: =iferror(INDIRECT(CONCATENATE(C10,"!","$K$7")),"") | K10: =iferror(INDIRECT(CONCATENATE(C10,"!","$K$8")),"") | L10: =iferror(INDIRECT(CONCATENATE(C10,"!","$K$9")),"")
A11: 2026/004 | C11: =concat(MID(A11,6,3),concat(" - ", B11)) -> 004 - | D11: =iferror(INDIRECT(CONCATENATE(C11,"!","$G$5")),"") | E11: =iferror(INDIRECT(CONCATENATE(C11,"!","$G$6")),"") | F11: =iferror(INDIRECT(CONCATENATE(C11,"!","$G$7")),"") | G11: =iferror(INDIRECT(CONCATENATE(C11,"!","$G$8")),"") | H11: =iferror(INDIRECT(CONCATENATE(C11,"!","$K$5")),"") | I11: =iferror(INDIRECT(CONCATENATE(C11,"!","$K$6")),"") | J11: =iferror(INDIRECT(CONCATENATE(C11,"!","$K$7")),"") | K11: =iferror(INDIRECT(CONCATENATE(C11,"!","$K$8")),"") | L11: =iferror(INDIRECT(CONCATENATE(C11,"!","$K$9")),"")
A12: 2026/005 | C12: =concat(MID(A12,6,3),concat(" - ", B12)) -> 005 - | D12: =iferror(INDIRECT(CONCATENATE(C12,"!","$G$5")),"") | E12: =iferror(INDIRECT(CONCATENATE(C12,"!","$G$6")),"") | F12: =iferror(INDIRECT(CONCATENATE(C12,"!","$G$7")),"") | G12: =iferror(INDIRECT(CONCATENATE(C12,"!","$G$8")),"") | H12: =iferror(INDIRECT(CONCATENATE(C12,"!","$K$5")),"") | I12: =iferror(INDIRECT(CONCATENATE(C12,"!","$K$6")),"") | J12: =iferror(INDIRECT(CONCATENATE(C12,"!","$K$7")),"") | K12: =iferror(INDIRECT(CONCATENATE(C12,"!","$K$8")),"") | L12: =iferror(INDIRECT(CONCATENATE(C12,"!","$K$9")),"")
A13: 2026/006 | C13: =concat(MID(A13,6,3),concat(" - ", B13)) -> 006 - | D13: =iferror(INDIRECT(CONCATENATE(C13,"!","$G$5")),"") | E13: =iferror(INDIRECT(CONCATENATE(C13,"!","$G$6")),"") | F13: =iferror(INDIRECT(CONCATENATE(C13,"!","$G$7")),"") | G13: =iferror(INDIRECT(CONCATENATE(C13,"!","$G$8")),"") | H13: =iferror(INDIRECT(CONCATENATE(C13,"!","$K$5")),"") | I13: =iferror(INDIRECT(CONCATENATE(C13,"!","$K$6")),"") | J13: =iferror(INDIRECT(CONCATENATE(C13,"!","$K$7")),"") | K13: =iferror(INDIRECT(CONCATENATE(C13,"!","$K$8")),"") | L13: =iferror(INDIRECT(CONCATENATE(C13,"!","$K$9")),"")
A14: 2026/007 | C14: =concat(MID(A14,6,3),concat(" - ", B14)) -> 007 - | D14: =iferror(INDIRECT(CONCATENATE(C14,"!","$G$5")),"") | E14: =iferror(INDIRECT(CONCATENATE(C14,"!","$G$6")),"") | F14: =iferror(INDIRECT(CONCATENATE(C14,"!","$G$7")),"") | G14: =iferror(INDIRECT(CONCATENATE(C14,"!","$G$8")),"") | H14: =iferror(INDIRECT(CONCATENATE(C14,"!","$K$5")),"") | I14: =iferror(INDIRECT(CONCATENATE(C14,"!","$K$6")),"") | J14: =iferror(INDIRECT(CONCATENATE(C14,"!","$K$7")),"") | K14: =iferror(INDIRECT(CONCATENATE(C14,"!","$K$8")),"") | L14: =iferror(INDIRECT(CONCATENATE(C14,"!","$K$9")),"")
A15: 2026/008 | C15: =concat(MID(A15,6,3),concat(" - ", B15)) -> 008 - | D15: =iferror(INDIRECT(CONCATENATE(C15,"!","$G$5")),"") | E15: =iferror(INDIRECT(CONCATENATE(C15,"!","$G$6")),"") | F15: =iferror(INDIRECT(CONCATENATE(C15,"!","$G$7")),"") | G15: =iferror(INDIRECT(CONCATENATE(C15,"!","$G$8")),"") | H15: =iferror(INDIRECT(CONCATENATE(C15,"!","$K$5")),"") | I15: =iferror(INDIRECT(CONCATENATE(C15,"!","$K$6")),"") | J15: =iferror(INDIRECT(CONCATENATE(C15,"!","$K$7")),"") | K15: =iferror(INDIRECT(CONCATENATE(C15,"!","$K$8")),"") | L15: =iferror(INDIRECT(CONCATENATE(C15,"!","$K$9")),"")
A16: 2026/009 | C16: =concat(MID(A16,6,3),concat(" - ", B16)) -> 009 - | D16: =iferror(INDIRECT(CONCATENATE(C16,"!","$G$5")),"") | E16: =iferror(INDIRECT(CONCATENATE(C16,"!","$G$6")),"") | F16: =iferror(INDIRECT(CONCATENATE(C16,"!","$G$7")),"") | G16: =iferror(INDIRECT(CONCATENATE(C16,"!","$G$8")),"") | H16: =iferror(INDIRECT(CONCATENATE(C16,"!","$K$5")),"") | I16: =iferror(INDIRECT(CONCATENATE(C16,"!","$K$6")),"") | J16: =iferror(INDIRECT(CONCATENATE(C16,"!","$K$7")),"") | K16: =iferror(INDIRECT(CONCATENATE(C16,"!","$K$8")),"") | L16: =iferror(INDIRECT(CONCATENATE(C16,"!","$K$9")),"")
A17: 2026/010 | C17: =concat(MID(A17,6,3),concat(" - ", B17)) -> 010 - | D17: =iferror(INDIRECT(CONCATENATE(C17,"!","$G$5")),"") | E17: =iferror(INDIRECT(CONCATENATE(C17,"!","$G$6")),"") | F17: =iferror(INDIRECT(CONCATENATE(C17,"!","$G$7")),"") | G17: =iferror(INDIRECT(CONCATENATE(C17,"!","$G$8")),"") | H17: =iferror(INDIRECT(CONCATENATE(C17,"!","$K$5")),"") | I17: =iferror(INDIRECT(CONCATENATE(C17,"!","$K$6")),"") | J17: =iferror(INDIRECT(CONCATENATE(C17,"!","$K$7")),"") | K17: =iferror(INDIRECT(CONCATENATE(C17,"!","$K$8")),"") | L17: =iferror(INDIRECT(CONCATENATE(C17,"!","$K$9")),"")
A18: 2026/011 | C18: =concat(MID(A18,6,3),concat(" - ", B18)) -> 011 - | D18: =iferror(INDIRECT(CONCATENATE(C18,"!","$G$5")),"") | E18: =iferror(INDIRECT(CONCATENATE(C18,"!","$G$6")),"") | F18: =iferror(INDIRECT(CONCATENATE(C18,"!","$G$7")),"") | G18: =iferror(INDIRECT(CONCATENATE(C18,"!","$G$8")),"") | H18: =iferror(INDIRECT(CONCATENATE(C18,"!","$K$5")),"") | I18: =iferror(INDIRECT(CONCATENATE(C18,"!","$K$6")),"") | J18: =iferror(INDIRECT(CONCATENATE(C18,"!","$K$7")),"") | K18: =iferror(INDIRECT(CONCATENATE(C18,"!","$K$8")),"") | L18: =iferror(INDIRECT(CONCATENATE(C18,"!","$K$9")),"")
A19: 2026/012 | C19: =concat(MID(A19,6,3),concat(" - ", B19)) -> 012 - | D19: =iferror(INDIRECT(CONCATENATE(C19,"!","$G$5")),"") | E19: =iferror(INDIRECT(CONCATENATE(C19,"!","$G$6")),"") | F19: =iferror(INDIRECT(CONCATENATE(C19,"!","$G$7")),"") | G19: =iferror(INDIRECT(CONCATENATE(C19,"!","$G$8")),"") | H19: =iferror(INDIRECT(CONCATENATE(C19,"!","$K$5")),"") | I19: =iferror(INDIRECT(CONCATENATE(C19,"!","$K$6")),"") | J19: =iferror(INDIRECT(CONCATENATE(C19,"!","$K$7")),"") | K19: =iferror(INDIRECT(CONCATENATE(C19,"!","$K$8")),"") | L19: =iferror(INDIRECT(CONCATENATE(C19,"!","$K$9")),"")
A20: 2026/013 | C20: =concat(MID(A20,6,3),concat(" - ", B20)) -> 013 - | D20: =iferror(INDIRECT(CONCATENATE(C20,"!","$G$5")),"") | E20: =iferror(INDIRECT(CONCATENATE(C20,"!","$G$6")),"") | F20: =iferror(INDIRECT(CONCATENATE(C20,"!","$G$7")),"") | G20: =iferror(INDIRECT(CONCATENATE(C20,"!","$G$8")),"") | H20: =iferror(INDIRECT(CONCATENATE(C20,"!","$K$5")),"") | I20: =iferror(INDIRECT(CONCATENATE(C20,"!","$K$6")),"") | J20: =iferror(INDIRECT(CONCATENATE(C20,"!","$K$7")),"") | K20: =iferror(INDIRECT(CONCATENATE(C20,"!","$K$8")),"") | L20: =iferror(INDIRECT(CONCATENATE(C20,"!","$K$9")),"")
C21: =concat(MID(A21,6,3),concat(" - ", B21)) -> - | D21: =iferror(INDIRECT(CONCATENATE(C21,"!","$F$5")),"") | E21: =iferror(INDIRECT(CONCATENATE(C21,"!","$F$6")),"") | F21: =iferror(INDIRECT(CONCATENATE(C21,"!","$F$7")),"") | G21: =iferror(INDIRECT(CONCATENATE(C21,"!","$F$8")),"") | H21: =iferror(INDIRECT(CONCATENATE(C21,"!","$K$5")),"") | I21: =iferror(INDIRECT(CONCATENATE(C21,"!","$K$6")),"") | J21: =iferror(INDIRECT(CONCATENATE(C21,"!","$K$7")),"") | K21: =iferror(INDIRECT(CONCATENATE(C21,"!","$K$8")),"") | L21: =iferror(INDIRECT(CONCATENATE(C21,"!","$K$9")),"")
C22: =concat(MID(A22,6,3),concat(" - ", B22)) -> - | D22: =iferror(INDIRECT(CONCATENATE(C22,"!","$F$5")),"") | E22: =iferror(INDIRECT(CONCATENATE(C22,"!","$F$6")),"") | F22: =iferror(INDIRECT(CONCATENATE(C22,"!","$F$7")),"") | G22: =iferror(INDIRECT(CONCATENATE(C22,"!","$F$8")),"") | H22: =iferror(INDIRECT(CONCATENATE(C22,"!","$K$5")),"") | I22: =iferror(INDIRECT(CONCATENATE(C22,"!","$K$6")),"") | J22: =iferror(INDIRECT(CONCATENATE(C22,"!","$K$7")),"") | K22: =iferror(INDIRECT(CONCATENATE(C22,"!","$K$8")),"") | L22: =iferror(INDIRECT(CONCATENATE(C22,"!","$K$9")),"")
C23: =concat(MID(A23,6,3),concat(" - ", B23)) -> - | D23: =iferror(INDIRECT(CONCATENATE(C23,"!","$F$5")),"") | E23: =iferror(INDIRECT(CONCATENATE(C23,"!","$F$6")),"") | F23: =iferror(INDIRECT(CONCATENATE(C23,"!","$F$7")),"") | G23: =iferror(INDIRECT(CONCATENATE(C23,"!","$F$8")),"") | H23: =iferror(INDIRECT(CONCATENATE(C23,"!","$K$5")),"") | I23: =iferror(INDIRECT(CONCATENATE(C23,"!","$K$6")),"") | J23: =iferror(INDIRECT(CONCATENATE(C23,"!","$K$7")),"") | K23: =iferror(INDIRECT(CONCATENATE(C23,"!","$K$8")),"") | L23: =iferror(INDIRECT(CONCATENATE(C23,"!","$K$9")),"")
C24: =concat(MID(A24,6,3),concat(" - ", B24)) -> - | D24: =iferror(INDIRECT(CONCATENATE(C24,"!","$F$5")),"") | E24: =iferror(INDIRECT(CONCATENATE(C24,"!","$F$6")),"") | F24: =iferror(INDIRECT(CONCATENATE(C24,"!","$F$7")),"") | G24: =iferror(INDIRECT(CONCATENATE(C24,"!","$F$8")),"") | H24: =iferror(INDIRECT(CONCATENATE(C24,"!","$K$5")),"") | I24: =iferror(INDIRECT(CONCATENATE(C24,"!","$K$6")),"") | J24: =iferror(INDIRECT(CONCATENATE(C24,"!","$K$7")),"") | K24: =iferror(INDIRECT(CONCATENATE(C24,"!","$K$8")),"") | L24: =iferror(INDIRECT(CONCATENATE(C24,"!","$K$9")),"")
C25: =concat(MID(A25,6,3),concat(" - ", B25)) -> - | D25: =iferror(INDIRECT(CONCATENATE(C25,"!","$F$5")),"") | E25: =iferror(INDIRECT(CONCATENATE(C25,"!","$F$6")),"") | F25: =iferror(INDIRECT(CONCATENATE(C25,"!","$F$7")),"") | G25: =iferror(INDIRECT(CONCATENATE(C25,"!","$F$8")),"") | H25: =iferror(INDIRECT(CONCATENATE(C25,"!","$K$5")),"") | I25: =iferror(INDIRECT(CONCATENATE(C25,"!","$K$6")),"") | J25: =iferror(INDIRECT(CONCATENATE(C25,"!","$K$7")),"") | K25: =iferror(INDIRECT(CONCATENATE(C25,"!","$K$8")),"") | L25: =iferror(INDIRECT(CONCATENATE(C25,"!","$K$9")),"")
C26: =concat(MID(A26,6,3),concat(" - ", B26)) -> - | D26: =iferror(INDIRECT(CONCATENATE(C26,"!","$F$5")),"") | E26: =iferror(INDIRECT(CONCATENATE(C26,"!","$F$6")),"") | F26: =iferror(INDIRECT(CONCATENATE(C26,"!","$F$7")),"") | G26: =iferror(INDIRECT(CONCATENATE(C26,"!","$F$8")),"") | H26: =iferror(INDIRECT(CONCATENATE(C26,"!","$K$5")),"") | I26: =iferror(INDIRECT(CONCATENATE(C26,"!","$K$6")),"") | J26: =iferror(INDIRECT(CONCATENATE(C26,"!","$K$7")),"") | K26: =iferror(INDIRECT(CONCATENATE(C26,"!","$K$8")),"") | L26: =iferror(INDIRECT(CONCATENATE(C26,"!","$K$9")),"")
C27: =concat(MID(A27,6,3),concat(" - ", B27)) -> - | D27: =iferror(INDIRECT(CONCATENATE(C27,"!","$F$5")),"") | E27: =iferror(INDIRECT(CONCATENATE(C27,"!","$F$6")),"") | F27: =iferror(INDIRECT(CONCATENATE(C27,"!","$F$7")),"") | G27: =iferror(INDIRECT(CONCATENATE(C27,"!","$F$8")),"") | H27: =iferror(INDIRECT(CONCATENATE(C27,"!","$K$5")),"") | I27: =iferror(INDIRECT(CONCATENATE(C27,"!","$K$6")),"") | J27: =iferror(INDIRECT(CONCATENATE(C27,"!","$K$7")),"") | K27: =iferror(INDIRECT(CONCATENATE(C27,"!","$K$8")),"") | L27: =iferror(INDIRECT(CONCATENATE(C27,"!","$K$9")),"")
C28: =concat(MID(A28,6,3),concat(" - ", B28)) -> - | D28: =iferror(INDIRECT(CONCATENATE(C28,"!","$F$5")),"") | E28: =iferror(INDIRECT(CONCATENATE(C28,"!","$F$6")),"") | F28: =iferror(INDIRECT(CONCATENATE(C28,"!","$F$7")),"") | G28: =iferror(INDIRECT(CONCATENATE(C28,"!","$F$8")),"") | H28: =iferror(INDIRECT(CONCATENATE(C28,"!","$K$5")),"") | I28: =iferror(INDIRECT(CONCATENATE(C28,"!","$K$6")),"") | J28: =iferror(INDIRECT(CONCATENATE(C28,"!","$K$7")),"") | K28: =iferror(INDIRECT(CONCATENATE(C28,"!","$K$8")),"") | L28: =iferror(INDIRECT(CONCATENATE(C28,"!","$K$9")),"")
C29: =concat(MID(A29,6,3),concat(" - ", B29)) -> - | D29: =iferror(INDIRECT(CONCATENATE(C29,"!","$F$5")),"") | E29: =iferror(INDIRECT(CONCATENATE(C29,"!","$F$6")),"") | F29: =iferror(INDIRECT(CONCATENATE(C29,"!","$F$7")),"") | G29: =iferror(INDIRECT(CONCATENATE(C29,"!","$F$8")),"") | H29: =iferror(INDIRECT(CONCATENATE(C29,"!","$K$5")),"") | I29: =iferror(INDIRECT(CONCATENATE(C29,"!","$K$6")),"") | J29: =iferror(INDIRECT(CONCATENATE(C29,"!","$K$7")),"") | K29: =iferror(INDIRECT(CONCATENATE(C29,"!","$K$8")),"") | L29: =iferror(INDIRECT(CONCATENATE(C29,"!","$K$9")),"")

Sheet 001 - Heisse Hetty
A1: Heisse Hetty
A2: Author: | B2: Tom & Sibren
A4: Gevraagd | E4: Verwacht | J4: Gemeten
A5: Volume | B5: 320 | E5: OG | G5: =if(D26=0,"",1+(G8/(258.6-((G8/258.2)*227.1)))) -> 1.0478662 | J5: OG
A6: Batch Volume | B6: 160 | E6: FG | G6: =if(D26=0,"",(G5-1)*(1-'001 - Heisse Hetty'!Attenuation)+1) -> 1.0095732 | J6: FG
A7: Attenuatie | B7: 0.8 | E7: ABV | G7: =if(D26=0,"",(G5-G6)*131.25/100) -> 0.050259526 | J7: ABV | K7: =IF(isblank(K6),"",(K5-K6)*131.25/100)
A8: Brouwefficientie | B8: 0.7 | E8: Plato | G8: =if(D26=0,"",SUMPRODUCT(D19:D25,F19:F25)*'001 - Heisse Hetty'!Brouwefficientie/'001 - Heisse Hetty'!Volume*100) -> 11.878125 | J8: Plato | K8: =if(ISBLANK(K5),"",(-1*616.868)+(1111.14*K5)-(630.272*POWER(K5,2))+(135.997*POWER(K5,3)))
A9: OG | B9: =('001 - Heisse Hetty'!FG-1)/(1-'001 - Heisse Hetty'!Attenuation)+1 -> 1.047619 | E9: IBU | G9: =IF(D44=0,"",R44) -> 9.8243024 | J9: Brouwefficientie | K9: =iferror(K8/G8*B8,"") -> 0
A10: FG | B10: =B11*(1-B7)/(B7*131.25/100)+1 -> 1.0095238 | E10: EBC | G10: =if(G26=0,"",1.4922*P26*0.6859*1.97) -> 6.0091239
A11: ABV | B11: 0.05
A12: Plato | B12: =(-1*616.868)+(1111.14*'001 - Heisse Hetty'!OG)-(630.272*POWER('001 - Heisse Hetty'!OG,2))+(135.997*POWER('001 - Heisse Hetty'!OG,3)) -> 11.821313
A14: Granen
A15: Totaal suikers nodig | D15: ='001 - Heisse Hetty'!Plato/100*'001 - Heisse Hetty'!Volume -> 37.828202 | E15: kg
A16: Totaal granen nodig | D16: =D15/F16/'001 - Heisse Hetty'!Brouwefficientie -> 67.55036 | E16: kg | F16: 0.8
A17: Graan type | C17: Voorraad | D17: Hoeveelheid | F17: Graanrendement | G17: EBC | H17: % van totaal | I17: Lot | J17: Per hL | L17: Per batch
C18: kg | D18: Massa | E18: kg | J18: Massa | K18: =E18 -> kg | L18: Massa | M18: kg | O18: Lovibond | P18: MCU
A19: Pilsmout | C19: =iferror(VLOOKUP(A19,'Voorraadfiche Grondstoffen'!$A$2:$D$100,4,False),"") -> 50 | D19: 60 | E19: =E$18 -> kg | F19: 0.78 | G19: 3 | H19: =if(isblank(D19),"",(D19/$D$26)) -> 0.85714286 | J19: =IF(ISBLANK(D19),"",D19/$B$5*100) -> 18.75 | K19: =K$18 -> kg | L19: =IF(ISBLANK(D19),"",D19/$B$5*$B$6) -> 30 | M19: =M$18 -> kg | O19: =(G19*0.508+0.76)/1.3546 -> 1.6861066 | P19: =D19/kgperpound*lpergallon/$B$5*O19 -> 2.6383565
A20: Tarwemout | C20: =iferror(VLOOKUP(A20,'Voorraadfiche Grondstoffen'!$A$2:$D$100,4,False),"") -> 80 | D20: 10 | E20: =E$18 -> kg | F20: 0.75 | G20: 2 | H20: =if(isblank(D20),"",(D20/$D$26)) -> 0.14285714 | J20: =IF(ISBLANK(D20),"",D20/$B$5*100) -> 3.125 | K20: =K$18 -> kg | L20: =IF(ISBLANK(D20),"",D20/$B$5*$B$6) -> 5 | M20: =M$18 -> kg | O20: =(G20*0.508+0.76)/1.3546 -> 1.3110881 | P20: =D20/kgperpound*lpergallon/$B$5*O20 -> 0.34192361
C21: =iferror(VLOOKUP(A21,'Voorraadfiche Grondstoffen'!$A$2:$D$100,4,False),"") | E21: =E$18 -> kg | H21: =if(isblank(D21),"",(D21/$D$26)) | J21: =IF(ISBLANK(D21),"",D21/$B$5*100) | K21: =K$18 -> kg | L21: =IF(ISBLANK(D21),"",D21/$B$5*$B$6) | M21: =M$18 -> kg | O21: =(G21*0.508+0.76)/1.3546 -> 0.56105123 | P21: =D21/kgperpound*lpergallon/$B$5*O21 -> 0
C22: =iferror(VLOOKUP(A22,'Voorraadfiche Grondstoffen'!$A$2:$D$100,4,False),"") | E22: =E$18 -> kg | H22: =if(isblank(D22),"",(D22/$D$26)) | J22: =IF(ISBLANK(D22),"",D22/$B$5*100) | K22: =K$18 -> kg | L22: =IF(ISBLANK(D22),"",D22/$B$5*$B$6) | M22: =M$18 -> kg | O22: =(G22*0.508+0.76)/1.3546 -> 0.56105123 | P22: =D22/kgperpound*lpergallon/$B$5*O22 -> 0
C23: =iferror(VLOOKUP(A23,'Voorraadfiche Grondstoffen'!$A$2:$D$100,4,False),"") | E23: =E$18 -> kg | H23: =if(isblank(D23),"",(D23/$D$26)) | J23: =IF(ISBLANK(D23),"",D23/$B$5*100) | K23: =K$18 -> kg | L23: =IF(ISBLANK(D23),"",D23/$B$5*$B$6) | M23: =M$18 -> kg | O23: =(G23*0.508+0.76)/1.3546 -> 0.56105123 | P23: =D23/kgperpound*lpergallon/$B$5*O23 -> 0
C24: =iferror(VLOOKUP(A24,'Voorraadfiche Grondstoffen'!$A$2:$D$100,4,False),"") | E24: =E$18 -> kg | H24: =if(isblank(D24),"",(D24/$D$26)) | J24: =IF(ISBLANK(D24),"",D24/$B$5*100) | K24: =K$18 -> kg | L24: =IF(ISBLANK(D24),"",D24/$B$5*$B$6) | M24: =M$18 -> kg | O24: =(G24*0.508+0.76)/1.3546 -> 0.56105123 | P24: =D24/kgperpound*lpergallon/$B$5*O24 -> 0
C25: =iferror(VLOOKUP(A25,'Voorraadfiche Grondstoffen'!$A$2:$D$100,4,False),"") | E25: =E$18 -> kg | H25: =if(isblank(D25),"",(D25/$D$26)) | J25: =IF(ISBLANK(D25),"",D25/$B$5*100) | K25: =K$18 -> kg | L25: =IF(ISBLANK(D25),"",D25/$B$5*$B$6) | M25: =M$18 -> kg | O25: =(G25*0.508+0.76)/1.3546 -> 0.56105123 | P25: =D25/kgperpound*lpergallon/$B$5*O25 -> 0
A26: TOTAL | D26: =SUM(D19:D25) -> 70 | E26: =E$18 -> kg | G26: =sum(G19:G25) -> 5 | J26: =SUM(J19:J25) -> 21.875 | K26: =K$18 -> kg | L26: =SUM(L19:L25) -> 35 | M26: =M$18 -> kg | P26: =SUM(P19:P25) -> 2.9802802
A28: Maisch
A29: Stap | D29: Temp | E29: Duur (min.)
A30: Protein Rest (52°C) | E30: 0
A31: Beta-Amylase Rest (63°C) | D31: 63 | E31: 45 | F31: =IF(D31="","",D30)
A32: Alpha-Amylase Rest (72°C) | F32: =IF(D32="","",D31)
A33: Mash Out (78°C) | E33: 5 | F33: =IF(D33="","",D32)
A34: TOTALS | E34: =SUM(E30:E33) -> 50 | F34: Minutes
A36: Hop
A37: Soort hop | D37: Hoeveelheid | F37: Pellet of bloem | G37: Kooktijd (min.) | H37: AA% | I37: Lot | J37: Per hL | L37: Per batch | O37: Biggness factor | P37: =1.65*POWER(0.000125,G5-1) -> 1.0731435
D38: Massa | E38: g | J38: Massa | K38: =E38 -> g | L38: Massa | M38: g | O38: Hops in oz | P38: Boil factor | Q38: Utilization | R38: IBU
A39: Hallertau Blanc | C39: =iferror(1000*VLOOKUP(A39,'Voorraadfiche Grondstoffen'!$F$2:$I$100,4,False),"") -> 4400 | D39: 200 | E39: =E$38 -> g | F39: Pellet | G39: 30 | H39: 7 | J39: =IF(ISBLANK(D39),"",D39/'001 - Heisse Hetty'!Volume*100) -> 62.5 | K39: =K$38 -> g | L39: =IF(ISBLANK(D39),"",D39/'001 - Heisse Hetty'!Volume*$B$6) -> 100 | M39: =M$38 -> g | O39: =D39*ozpergram -> 7.054792 | P39: =(1-POWER(2.71828182845904,((-0.04)*G39)))/4.15 -> 0.16838694 | Q39: =P39*$P$37 -> 0.18070335 | R39: =IF(F39="Leaf", ((H39 *O39) *Q39 * 74.9) / '001 - Heisse Hetty'!Volume*3.785, ((H39 *O39) * (Q39*1.1) * 74.9) / '001 - Heisse Hetty'!Volume*3.785) -> 8.696387
A40: Calista | C40: =iferror(1000*VLOOKUP(A40,'Voorraadfiche Grondstoffen'!$F$2:$I$100,4,False),"") -> 1800 | D40: 200 | E40: =E$38 -> g | F40: Pellet | G40: 5 | H40: 3.5 | J40: =IF(ISBLANK(D40),"",D40/'001 - Heisse Hetty'!Volume*100) -> 62.5 | K40: =K$38 -> g | L40: =IF(ISBLANK(D40),"",D40/'001 - Heisse Hetty'!Volume*$B$6) -> 100 | M40: =M$38 -> g | O40: =D40*ozpergram -> 7.054792 | P40: =(1-POWER(2.71828182845904,((-0.04)*G40)))/4.15 -> 0.043679337 | Q40: =P40*$P$37 -> 0.046874196 | R40: =IF(F40="Leaf", ((H40 *O40) *Q40 * 74.9) / '001 - Heisse Hetty'!Volume*3.785, ((H40 *O40) * (Q40*1.1) * 74.9) / '001 - Heisse Hetty'!Volume*3.785) -> 1.1279153
A41: Calista | C41: =iferror(1000*VLOOKUP(A41,'Voorraadfiche Grondstoffen'!$F$2:$I$100,4,False),"") -> 1800 | D41: 800 | E41: =E$38 -> g | F41: Pellet | G41: 0 | H41: 0 | J41: =IF(ISBLANK(D41),"",D41/'001 - Heisse Hetty'!Volume*100) -> 250 | K41: =K$38 -> g | L41: =IF(ISBLANK(D41),"",D41/'001 - Heisse Hetty'!Volume*$B$6) -> 400 | M41: =M$38 -> g | O41: =D41*ozpergram -> 28.219168 | P41: =(1-POWER(2.71828182845904,((-0.04)*G41)))/4.15 -> 0 | Q41: =P41*$P$37 -> 0 | R41: =IF(F41="Leaf", ((H41 *O41) *Q41 * 74.9) / '001 - Heisse Hetty'!Volume*3.785, ((H41 *O41) * (Q41*1.1) * 74.9) / '001 - Heisse Hetty'!Volume*3.785) -> 0
C42: =iferror(1000*VLOOKUP(A42,'Voorraadfiche Grondstoffen'!$F$2:$I$100,4,False),"") | E42: =E$38 -> g | F42: Pellet | J42: =IF(ISBLANK(D42),"",D42/'001 - Heisse Hetty'!Volume*100) | K42: =K$38 -> g | L42: =IF(ISBLANK(D42),"",D42/'001 - Heisse Hetty'!Volume*$B$6) | M42: =M$38 -> g | O42: =D42*ozpergram -> 0 | P42: =(1-POWER(2.71828182845904,((-0.04)*G42)))/4.15 -> 0 | Q42: =P42*$P$37 -> 0 | R42: =IF(F42="Leaf", ((H42 *O42) *Q42 * 74.9) / '001 - Heisse Hetty'!Volume*3.785, ((H42 *O42) * (Q42*1.1) * 74.9) / '001 - Heisse Hetty'!Volume*3.785) -> 0
C43: =iferror(1000*VLOOKUP(A43,'Voorraadfiche Grondstoffen'!$F$2:$I$100,4,False),"") | E43: =E$38 -> g | J43: =IF(ISBLANK(D43),"",D43/'001 - Heisse Hetty'!Volume*100) | K43: =K$38 -> g | L43: =IF(ISBLANK(D43),"",D43/'001 - Heisse Hetty'!Volume*$B$6) | M43: =M$38 -> g | O43: =D43*ozpergram -> 0 | P43: =(1-POWER(2.71828182845904,((-0.04)*G43)))/4.15 -> 0 | Q43: =P43*$P$37 -> 0 | R43: =IF(F43="Leaf", ((H43 *O43) *Q43 * 74.9) / '001 - Heisse Hetty'!Volume*3.785, ((H43 *O43) * (Q43*1.1) * 74.9) / '001 - Heisse Hetty'!Volume*3.785) -> 0
A44: TOTAL | D44: =SUM(D39:D43) -> 1200 | E44: =E$38 -> g | J44: =SUM(J39:J43) -> 375 | K44: =K$38 -> g | L44: =SUM(L39:L43) -> 600 | M44: =M$38 -> g | R44: =sum(R39:R43) -> 9.8243024
...

Sheet 002 - Exquise Elise
A1: Exquise Elise
A2: Author: | B2: Tom & Sibren
A4: Gevraagd | E4: Verwacht | J4: Gemeten
A5: Volume | B5: 320 | E5: OG | G5: =if(D26=0,"",1+(G8/(258.6-((G8/258.2)*227.1)))) -> 1.0493378 | J5: OG
A6: Batch Volume | B6: 160 | E6: FG | G6: =if(D26=0,"",(G5-1)*(1-'002 - Exquise Elise'!Attenuation)+1) -> 1.0024669 | J6: FG
A7: Attenuatie | B7: 0.95 | E7: ABV | G7: =if(D26=0,"",(G5-G6)*131.25/100) -> 0.061518123 | J7: ABV | K7: =IF(isblank(K6),"",(K5-K6)*131.25/100)
A8: Brouwefficientie | B8: 0.7 | E8: Plato | G8: =if(D26=0,"",SUMPRODUCT(D19:D25,F19:F25)*'002 - Exquise Elise'!Brouwefficientie/'002 - Exquise Elise'!Volume*100) -> 12.228125 | J8: Plato | K8: =if(ISBLANK(K5),"",(-1*616.868)+(1111.14*K5)-(630.272*POWER(K5,2))+(135.997*POWER(K5,3)))
A9: OG | B9: =('002 - Exquise Elise'!FG-1)/(1-'002 - Exquise Elise'!Attenuation)+1 -> 1.0481203 | E9: IBU | G9: =IF(D44=0,"",R44) -> 0 | J9: Brouwefficientie | K9: =iferror(K8/G8*B8,"") -> 0
A10: FG | B10: =B11*(1-B7)/(B7*131.25/100)+1 -> 1.002406 | E10: EBC | G10: =if(G26=0,"",1.4922*P26*0.6859*1.97) -> 5.836381
A11: ABV | B11: 0.06
A12: Plato | B12: =(-1*616.868)+(1111.14*'002 - Exquise Elise'!OG)-(630.272*POWER('002 - Exquise Elise'!OG,2))+(135.997*POWER('002 - Exquise Elise'!OG,3)) -> 11.940732
A14: Granen
A15: Totaal suikers nodig | D15: ='002 - Exquise Elise'!Plato/100*'002 - Exquise Elise'!Volume -> 38.210342 | E15: kg
A16: Totaal granen nodig | D16: =D15/F16/'002 - Exquise Elise'!Brouwefficientie -> 68.232754 | E16: kg | F16: 0.8
A17: Graan type | C17: Voorraad | D17: Hoeveelheid | F17: Graanrendement | G17: EBC | H17: % van totaal | I17: Lot | J17: Per hL | L17: Per batch
C18: kg | D18: Massa | E18: kg | J18: Massa | K18: =E18 -> kg | L18: Massa | M18: kg | O18: Lovibond | P18: MCU
A19: Pilsmout | C19: =iferror(VLOOKUP(A19,'Voorraadfiche Grondstoffen'!$A$2:$D$100,4,False),"") -> 50 | D19: 50 | E19: =E$18 -> kg | F19: 0.78 | G19: 3 | H19: =if(isblank(D19),"",(D19/$D$26)) -> 0.68965517 | J19: =IF(ISBLANK(D19),"",D19/$B$5*100) -> 15.625 | K19: =K$18 -> kg | L19: =IF(ISBLANK(D19),"",D19/$B$5*$B$6) -> 25 | M19: =M$18 -> kg | O19: =(G19*0.508+0.76)/1.3546 -> 1.6861066 | P19: =D19/kgperpound*lpergallon/$B$5*O19 -> 2.1986305
A20: Tarwemout | C20: =iferror(VLOOKUP(A20,'Voorraadfiche Grondstoffen'!$A$2:$D$100,4,False),"") -> 80 | D20: 15 | E20: =E$18 -> kg | F20: 0.75 | G20: 2 | H20: =if(isblank(D20),"",(D20/$D$26)) -> 0.20689655 | J20: =IF(ISBLANK(D20),"",D20/$B$5*100) -> 4.6875 | K20: =K$18 -> kg | L20: =IF(ISBLANK(D20),"",D20/$B$5*$B$6) -> 7.5 | M20: =M$18 -> kg | O20: =(G20*0.508+0.76)/1.3546 -> 1.3110881 | P20: =D20/kgperpound*lpergallon/$B$5*O20 -> 0.51288542
A21: Tarwe | C21: =iferror(VLOOKUP(A21,'Voorraadfiche Grondstoffen'!$A$2:$D$100,4,False),"") | D21: 5 | E21: =E$18 -> kg | F21: 0.78 | G21: 1 | H21: =if(isblank(D21),"",(D21/$D$26)) -> 0.068965517 | J21: =IF(ISBLANK(D21),"",D21/$B$5*100) -> 1.5625 | K21: =K$18 -> kg | L21: =IF(ISBLANK(D21),"",D21/$B$5*$B$6) -> 2.5 | M21: =M$18 -> kg | O21: =(G21*0.508+0.76)/1.3546 -> 0.93606969 | P21: =D21/kgperpound*lpergallon/$B$5*O21 -> 0.12206057
A22: Havervlokken | C22: =iferror(VLOOKUP(A22,'Voorraadfiche Grondstoffen'!$A$2:$D$100,4,False),"") -> 5.5 | D22: 2.5 | E22: =E$18 -> kg | F22: 0.7 | G22: 1 | H22: =if(isblank(D22),"",(D22/$D$26)) -> 0.034482759 | J22: =IF(ISBLANK(D22),"",D22/$B$5*100) -> 0.78125 | K22: =K$18 -> kg | L22: =IF(ISBLANK(D22),"",D22/$B$5*$B$6) -> 1.25 | M22: =M$18 -> kg | O22: =(G22*0.508+0.76)/1.3546 -> 0.93606969 | P22: =D22/kgperpound*lpergallon/$B$5*O22 -> 0.061030285
C23: =iferror(VLOOKUP(A23,'Voorraadfiche Grondstoffen'!$A$2:$D$100,4,False),"") | E23: =E$18 -> kg | H23: =if(isblank(D23),"",(D23/$D$26)) | J23: =IF(ISBLANK(D23),"",D23/$B$5*100) | K23: =K$18 -> kg | L23: =IF(ISBLANK(D23),"",D23/$B$5*$B$6) | M23: =M$18 -> kg | O23: =(G23*0.508+0.76)/1.3546 -> 0.56105123 | P23: =D23/kgperpound*lpergallon/$B$5*O23 -> 0
C24: =iferror(VLOOKUP(A24,'Voorraadfiche Grondstoffen'!$A$2:$D$100,4,False),"") | E24: =E$18 -> kg | H24: =if(isblank(D24),"",(D24/$D$26)) | J24: =IF(ISBLANK(D24),"",D24/$B$5*100) | K24: =K$18 -> kg | L24: =IF(ISBLANK(D24),"",D24/$B$5*$B$6) | M24: =M$18 -> kg | O24: =(G24*0.508+0.76)/1.3546 -> 0.56105123 | P24: =D24/kgperpound*lpergallon/$B$5*O24 -> 0
C25: =iferror(VLOOKUP(A25,'Voorraadfiche Grondstoffen'!$A$2:$D$100,4,False),"") | E25: =E$18 -> kg | H25: =if(isblank(D25),"",(D25/$D$26)) | J25: =IF(ISBLANK(D25),"",D25/$B$5*100) | K25: =K$18 -> kg | L25: =IF(ISBLANK(D25),"",D25/$B$5*$B$6) | M25: =M$18 -> kg | O25: =(G25*0.508+0.76)/1.3546 -> 0.56105123 | P25: =D25/kgperpound*lpergallon/$B$5*O25 -> 0
A26: TOTAL | D26: =SUM(D19:D25) -> 72.5 | E26: =E$18 -> kg | G26: =sum(G19:G25) -> 7 | J26: =SUM(J19:J25) -> 22.65625 | K26: =K$18 -> kg | L26: =SUM(L19:L25) -> 36.25 | M26: =M$18 -> kg | P26: =SUM(P19:P25) -> 2.8946067
A28: Maisch
A29: Stap | D29: Temp | E29: Duur (min.)
A30: Protein Rest (52°C) | E30: 0
A31: Beta-Amylase Rest (63°C) | D31: 63 | E31: 45 | F31: =IF(D31="","",D30)
A32: Alpha-Amylase Rest (72°C) | F32: =IF(D32="","",D31)
A33: Mash Out (78°C) | E33: 5 | F33: =IF(D33="","",D32)
A34: TOTALS | E34: =SUM(E30:E33) -> 50 | F34: Minutes
A36: Hop
A37: Soort hop | D37: Hoeveelheid | F37: Pellet of bloem | G37: Kooktijd (min.) | H37: AA% | I37: Lot | J37: Per hL | L37: Per batch | O37: Biggness factor | P37: =1.65*POWER(0.000125,G5-1) -> 1.0590438
D38: Massa | E38: g | J38: Massa | K38: =E38 -> g | L38: Massa | M38: g | O38: Hops in oz | P38: Boil factor | Q38: Utilization | R38: IBU
C39: =iferror(1000*VLOOKUP(A39,'Voorraadfiche Grondstoffen'!$F$2:$I$100,4,False),"") | E39: =E$38 -> g | F39: Pellet | J39: =IF(ISBLANK(D39),"",D39/'002 - Exquise Elise'!Volume*100) | K39: =K$38 -> g | L39: =IF(ISBLANK(D39),"",D39/'002 - Exquise Elise'!Volume*$B$6) | M39: =M$38 -> g | O39: =D39*ozpergram -> 0 | P39: =(1-POWER(2.71828182845904,((-0.04)*G39)))/4.15 -> 0 | Q39: =P39*$P$37 -> 0 | R39: =IF(F39="Leaf", ((H39 *O39) *Q39 * 74.9) / '002 - Exquise Elise'!Volume*3.785, ((H39 *O39) * (Q39*1.1) * 74.9) / '002 - Exquise Elise'!Volume*3.785) -> 0
C40: =iferror(1000*VLOOKUP(A40,'Voorraadfiche Grondstoffen'!$F$2:$I$100,4,False),"") | E40: =E$38 -> g | F40: Pellet | G40: 0 | J40: =IF(ISBLANK(D40),"",D40/'002 - Exquise Elise'!Volume*100) | K40: =K$38 -> g | L40: =IF(ISBLANK(D40),"",D40/'002 - Exquise Elise'!Volume*$B$6) | M40: =M$38 -> g | O40: =D40*ozpergram -> 0 | P40: =(1-POWER(2.71828182845904,((-0.04)*G40)))/4.15 -> 0 | Q40: =P40*$P$37 -> 0 | R40: =IF(F40="Leaf", ((H40 *O40) *Q40 * 74.9) / '002 - Exquise Elise'!Volume*3.785, ((H40 *O40) * (Q40*1.1) * 74.9) / '002 - Exquise Elise'!Volume*3.785) -> 0
C41: =iferror(1000*VLOOKUP(A41,'Voorraadfiche Grondstoffen'!$F$2:$I$100,4,False),"") | E41: =E$38 -> g | F41: Pellet | G41: 0 | H41: 0 | J41: =IF(ISBLANK(D41),"",D41/'002 - Exquise Elise'!Volume*100) | K41: =K$38 -> g | L41: =IF(ISBLANK(D41),"",D41/'002 - Exquise Elise'!Volume*$B$6) | M41: =M$38 -> g | O41: =D41*ozpergram -> 0 | P41: =(1-POWER(2.71828182845904,((-0.04)*G41)))/4.15 -> 0 | Q41: =P41*$P$37 -> 0 | R41: =IF(F41="Leaf", ((H41 *O41) *Q41 * 74.9) / '002 - Exquise Elise'!Volume*3.785, ((H41 *O41) * (Q41*1.1) * 74.9) / '002 - Exquise Elise'!Volume*3.785) -> 0
A42: Motueka | C42: =iferror(1000*VLOOKUP(A42,'Voorraadfiche Grondstoffen'!$F$2:$I$100,4,False),"") -> 0 | D42: 1000 | E42: =E$38 -> g | F42: Pellet | G42: 0 | H42: 8 | J42: =IF(ISBLANK(D42),"",D42/'002 - Exquise Elise'!Volume*100) -> 312.5 | K42: =K$38 -> g | L42: =IF(ISBLANK(D42),"",D42/'002 - Exquise Elise'!Volume*$B$6) -> 500 | M42: =M$38 -> g | O42: =D42*ozpergram -> 35.27396 | P42: =(1-POWER(2.71828182845904,((-0.04)*G42)))/4.15 -> 0 | Q42: =P42*$P$37 -> 0 | R42: =IF(F42="Leaf", ((H42 *O42) *Q42 * 74.9) / '002 - Exquise Elise'!Volume*3.785, ((H42 *O42) * (Q42*1.1) * 74.9) / '002 - Exquise Elise'!Volume*3.785) -> 0
C43: =iferror(1000*VLOOKUP(A43,'Voorraadfiche Grondstoffen'!$F$2:$I$100,4,False),"") | E43: =E$38 -> g | J43: =IF(ISBLANK(D43),"",D43/'002 - Exquise Elise'!Volume*100) | K43: =K$38 -> g | L43: =IF(ISBLANK(D43),"",D43/'002 - Exquise Elise'!Volume*$B$6) | M43: =M$38 -> g | O43: =D43*ozpergram -> 0 | P43: =(1-POWER(2.71828182845904,((-0.04)*G43)))/4.15 -> 0 | Q43: =P43*$P$37 -> 0 | R43: =IF(F43="Leaf", ((H43 *O43) *Q43 * 74.9) / '002 - Exquise Elise'!Volume*3.785, ((H43 *O43) * (Q43*1.1) * 74.9) / '002 - Exquise Elise'!Volume*3.785) -> 0
A44: TOTAL | D44: =SUM(D39:D43) -> 1000 | E44: =E$38 -> g | J44: =SUM(J39:J43) -> 312.5 | K44: =K$38 -> g | L44: =SUM(L39:L43) -> 500 | M44: =M$38 -> g | R44: =sum(R39:R43) -> 0
...

Sheet 003 - Mystieke Margarita
A1: Mystieke Margarita
A2: Author: | B2: Tom & Sibren
A4: Gevraagd | E4: Verwacht | J4: Gemeten
A5: Volume | B5: 320 | E5: OG | G5: =if(D26=0,"",1+(G8/(258.6-((G8/258.2)*227.1)))) -> 1.0540532 | J5: OG | K5: 1.044
A6: Batch Volume | B6: 160 | E6: FG | G6: =if(D26=0,"",(G5-1)*(1-'003 - Mystieke Margarita'!Attenuation)+1) -> 1.0108106 | J6: FG
A7: Attenuatie | B7: 0.8 | E7: ABV | G7: =if(D26=0,"",(G5-G6)*131.25/100) -> 0.05675581 | J7: ABV | K7: =IF(isblank(K6),"",(K5-K6)*131.25/100)
A8: Brouwefficientie | B8: 0.7 | E8: Plato | G8: =if(D26=0,"",SUMPRODUCT(D19:D25,F19:F25)*'003 - Mystieke Margarita'!Brouwefficientie/'003 - Mystieke Margarita'!Volume*100) -> 13.34375 | J8: Plato | K8: =if(ISBLANK(K5),"",(-1*616.868)+(1111.14*K5)-(630.272*POWER(K5,2))+(135.997*POWER(K5,3))) -> 10.956077
A9: OG | B9: =('003 - Mystieke Margarita'!FG-1)/(1-'003 - Mystieke Margarita'!Attenuation)+1 -> 1.047619 | E9: IBU | G9: =IF(D44=0,"",R44) -> 0 | J9: Brouwefficientie | K9: =iferror(K8/G8*B8,"") -> 0.57474501
A10: FG | B10: =B11*(1-B7)/(B7*131.25/100)+1 -> 1.0095238 | E10: EBC | G10: =if(G26=0,"",1.4922*P26*0.6859*1.97) -> 7.7831352
A11: ABV | B11: 0.05
A12: Plato | B12: =(-1*616.868)+(1111.14*'003 - Mystieke Margarita'!OG)-(630.272*POWER('003 - Mystieke Margarita'!OG,2))+(135.997*POWER('003 - Mystieke Margarita'!OG,3)) -> 11.821313
A14: Granen
A15: Totaal suikers nodig | D15: ='003 - Mystieke Margarita'!Plato/100*'003 - Mystieke Margarita'!Volume -> 37.828202 | E15: kg
A16: Totaal granen nodig | D16: =D15/F16/'003 - Mystieke Margarita'!Brouwefficientie -> 67.55036 | E16: kg | F16: 0.8
A17: Graan type | C17: Voorraad | D17: Hoeveelheid | F17: Graanrendement | G17: EBC | H17: % van totaal | I17: Lot | J17: Per hL | L17: Per batch
C18: kg | D18: Massa | E18: kg | J18: Massa | K18: =E18 -> kg | L18: Massa | M18: kg | O18: Lovibond | P18: MCU
A19: Pilsmout | C19: =iferror(VLOOKUP(A19,'Voorraadfiche Grondstoffen'!$A$2:$D$100,4,False),"") -> 50 | D19: 50 | E19: =E$18 -> kg | F19: 0.78 | G19: 3 | H19: =if(isblank(D19),"",(D19/$D$26)) -> 0.625 | J19: =IF(ISBLANK(D19),"",D19/$B$5*100) -> 15.625 | K19: =K$18 -> kg | L19: =IF(ISBLANK(D19),"",D19/$B$5*$B$6) -> 25 | M19: =M$18 -> kg | O19: =(G19*0.508+0.76)/1.3546 -> 1.6861066 | P19: =D19/kgperpound*lpergallon/$B$5*O19 -> 2.1986305
A20: Tarwemout | C20: =iferror(VLOOKUP(A20,'Voorraadfiche Grondstoffen'!$A$2:$D$100,4,False),"") -> 80 | D20: 15 | E20: =E$18 -> kg | F20: 0.75 | G20: 2 | H20: =if(isblank(D20),"",(D20/$D$26)) -> 0.1875 | J20: =IF(ISBLANK(D20),"",D20/$B$5*100) -> 4.6875 | K20: =K$18 -> kg | L20: =IF(ISBLANK(D20),"",D20/$B$5*$B$6) -> 7.5 | M20: =M$18 -> kg | O20: =(G20*0.508+0.76)/1.3546 -> 1.3110881 | P20: =D20/kgperpound*lpergallon/$B$5*O20 -> 0.51288542
A21: Tarwe | C21: =iferror(VLOOKUP(A21,'Voorraadfiche Grondstoffen'!$A$2:$D$100,4,False),"") | D21: 0 | E21: =E$18 -> kg | F21: 0.78 | G21: 1 | H21: =if(isblank(D21),"",(D21/$D$26)) -> 0 | J21: =IF(ISBLANK(D21),"",D21/$B$5*100) -> 0 | K21: =K$18 -> kg | L21: =IF(ISBLANK(D21),"",D21/$B$5*$B$6) -> 0 | M21: =M$18 -> kg | O21: =(G21*0.508+0.76)/1.3546 -> 0.93606969 | P21: =D21/kgperpound*lpergallon/$B$5*O21 -> 0
A22: Havervlokken | C22: =iferror(VLOOKUP(A22,'Voorraadfiche Grondstoffen'!$A$2:$D$100,4,False),"") -> 5.5 | D22: 10 | E22: =E$18 -> kg | F22: 0.7 | G22: 1 | H22: =if(isblank(D22),"",(D22/$D$26)) -> 0.125 | J22: =IF(ISBLANK(D22),"",D22/$B$5*100) -> 3.125 | K22: =K$18 -> kg | L22: =IF(ISBLANK(D22),"",D22/$B$5*$B$6) -> 5 | M22: =M$18 -> kg | O22: =(G22*0.508+0.76)/1.3546 -> 0.93606969 | P22: =D22/kgperpound*lpergallon/$B$5*O22 -> 0.24412114
A23: Carapils | C23: =iferror(VLOOKUP(A23,'Voorraadfiche Grondstoffen'!$A$2:$D$100,4,False),"") | D23: 3 | E23: =E$18 -> kg | F23: 0.75 | G23: 5 | H23: =if(isblank(D23),"",(D23/$D$26)) -> 0.0375 | J23: =IF(ISBLANK(D23),"",D23/$B$5*100) -> 0.9375 | K23: =K$18 -> kg | L23: =IF(ISBLANK(D23),"",D23/$B$5*$B$6) -> 1.5 | M23: =M$18 -> kg | O23: =(G23*0.508+0.76)/1.3546 -> 2.4361435 | P23: =D23/kgperpound*lpergallon/$B$5*O23 -> 0.19059931
A24: CaraHell | C24: =iferror(VLOOKUP(A24,'Voorraadfiche Grondstoffen'!$A$2:$D$100,4,False),"") | D24: 1 | E24: =E$18 -> kg | F24: 0.75 | G24: 20 | H24: =if(isblank(D24),"",(D24/$D$26)) -> 0.0125 | J24: =IF(ISBLANK(D24),"",D24/$B$5*100) -> 0.3125 | K24: =K$18 -> kg | L24: =IF(ISBLANK(D24),"",D24/$B$5*$B$6) -> 0.5 | M24: =M$18 -> kg | O24: =(G24*0.508+0.76)/1.3546 -> 8.0614203 | P24: =D24/kgperpound*lpergallon/$B$5*O24 -> 0.21023682
A25: CaraRed | C25: =iferror(VLOOKUP(A25,'Voorraadfiche Grondstoffen'!$A$2:$D$100,4,False),"") | D25: 1 | E25: =E$18 -> kg | F25: 0.75 | G25: 50 | H25: =if(isblank(D25),"",(D25/$D$26)) -> 0.0125 | J25: =IF(ISBLANK(D25),"",D25/$B$5*100) -> 0.3125 | K25: =K$18 -> kg | L25: =IF(ISBLANK(D25),"",D25/$B$5*$B$6) -> 0.5 | M25: =M$18 -> kg | O25: =(G25*0.508+0.76)/1.3546 -> 19.311974 | P25: =D25/kgperpound*lpergallon/$B$5*O25 -> 0.50364424
A26: TOTAL | D26: =SUM(D19:D25) -> 80 | E26: =E$18 -> kg | G26: =sum(G19:G25) -> 82 | J26: =SUM(J19:J25) -> 25 | K26: =K$18 -> kg | L26: =SUM(L19:L25) -> 40 | M26: =M$18 -> kg | P26: =SUM(P19:P25) -> 3.8601174
A28: Maisch
A29: Stap | D29: Temp | E29: Duur (min.)
A30: Protein Rest (52°C) | E30: 0
A31: Beta-Amylase Rest (63°C) | E31: 0 | F31: =IF(D31="","",D30)
A32: Alpha-Amylase Rest (72°C) | E32: 45 | F32: =IF(D32="","",D31)
A33: Mash Out (78°C) | E33: 5 | F33: =IF(D33="","",D32)
A34: TOTALS | E34: =SUM(E30:E33) -> 50 | F34: Minutes
A36: Hop
A37: Soort hop | D37: Hoeveelheid | F37: Pellet of bloem | G37: Kooktijd (min.) | H37: AA% | I37: Lot | J37: Per hL | L37: Per batch | O37: Biggness factor | P37: =1.65*POWER(0.000125,G5-1) -> 1.0151019
D38: Massa | E38: g | J38: Massa | K38: =E38 -> g | L38: Massa | M38: g | O38: Hops in oz | P38: Boil factor | Q38: Utilization | R38: IBU
E39: =E$38 -> g | F39: Pellet | J39: =IF(ISBLANK(D39),"",D39/'003 - Mystieke Margarita'!Volume*100) | K39: =K$38 -> g | L39: =IF(ISBLANK(D39),"",D39/'003 - Mystieke Margarita'!Volume*$B$6) | M39: =M$38 -> g | O39: =D39*ozpergram -> 0 | P39: =(1-POWER(2.71828182845904,((-0.04)*G39)))/4.15 -> 0 | Q39: =P39*$P$37 -> 0 | R39: =IF(F39="Leaf", ((H39 *O39) *Q39 * 74.9) / '003 - Mystieke Margarita'!Volume*3.785, ((H39 *O39) * (Q39*1.1) * 74.9) / '003 - Mystieke Margarita'!Volume*3.785) -> 0
E40: =E$38 -> g | F40: Pellet | J40: =IF(ISBLANK(D40),"",D40/'003 - Mystieke Margarita'!Volume*100) | K40: =K$38 -> g | L40: =IF(ISBLANK(D40),"",D40/'003 - Mystieke Margarita'!Volume*$B$6) | M40: =M$38 -> g | O40: =D40*ozpergram -> 0 | P40: =(1-POWER(2.71828182845904,((-0.04)*G40)))/4.15 -> 0 | Q40: =P40*$P$37 -> 0 | R40: =IF(F40="Leaf", ((H40 *O40) *Q40 * 74.9) / '003 - Mystieke Margarita'!Volume*3.785, ((H40 *O40) * (Q40*1.1) * 74.9) / '003 - Mystieke Margarita'!Volume*3.785) -> 0
E41: =E$38 -> g | F41: Pellet | J41: =IF(ISBLANK(D41),"",D41/'003 - Mystieke Margarita'!Volume*100) | K41: =K$38 -> g | L41: =IF(ISBLANK(D41),"",D41/'003 - Mystieke Margarita'!Volume*$B$6) | M41: =M$38 -> g | O41: =D41*ozpergram -> 0 | P41: =(1-POWER(2.71828182845904,((-0.04)*G41)))/4.15 -> 0 | Q41: =P41*$P$37 -> 0 | R41: =IF(F41="Leaf", ((H41 *O41) *Q41 * 74.9) / '003 - Mystieke Margarita'!Volume*3.785, ((H41 *O41) * (Q41*1.1) * 74.9) / '003 - Mystieke Margarita'!Volume*3.785) -> 0
A42: Motueka | C42: =iferror(1000*VLOOKUP(A42,'Voorraadfiche Grondstoffen'!$F$2:$I$100,4,False),"") -> 0 | D42: 1000 | E42: =E$38 -> g | F42: Pellet | J42: =IF(ISBLANK(D42),"",D42/'003 - Mystieke Margarita'!Volume*100) -> 312.5 | K42: =K$38 -> g | L42: =IF(ISBLANK(D42),"",D42/'003 - Mystieke Margarita'!Volume*$B$6) -> 500 | M42: =M$38 -> g | O42: =D42*ozpergram -> 35.27396 | P42: =(1-POWER(2.71828182845904,((-0.04)*G42)))/4.15 -> 0 | Q42: =P42*$P$37 -> 0 | R42: =IF(F42="Leaf", ((H42 *O42) *Q42 * 74.9) / '003 - Mystieke Margarita'!Volume*3.785, ((H42 *O42) * (Q42*1.1) * 74.9) / '003 - Mystieke Margarita'!Volume*3.785) -> 0
C43: =iferror(1000*VLOOKUP(A43,'Voorraadfiche Grondstoffen'!$F$2:$I$100,4,False),"") | E43: =E$38 -> g | J43: =IF(ISBLANK(D43),"",D43/'003 - Mystieke Margarita'!Volume*100) | K43: =K$38 -> g | L43: =IF(ISBLANK(D43),"",D43/'003 - Mystieke Margarita'!Volume*$B$6) | M43: =M$38 -> g | O43: =D43*ozpergram -> 0 | P43: =(1-POWER(2.71828182845904,((-0.04)*G43)))/4.15 -> 0 | Q43: =P43*$P$37 -> 0 | R43: =IF(F43="Leaf", ((H43 *O43) *Q43 * 74.9) / '003 - Mystieke Margarita'!Volume*3.785, ((H43 *O43) * (Q43*1.1) * 74.9) / '003 - Mystieke Margarita'!Volume*3.785) -> 0
A44: TOTAL | D44: =SUM(D39:D43) -> 1000 | E44: =E$38 -> g | J44: =SUM(J39:J43) -> 312.5 | K44: =K$38 -> g | L44: =SUM(L39:L43) -> 500 | M44: =M$38 -> g | R44: =sum(R39:R43) -> 0
...

Sheet 004 - Elegante Elodie
A1: Elegante Elodie
A2: Author: | B2: Tom & Sibren
A4: Gevraagd | E4: Verwacht | J4: Gemeten
A5: Volume | B5: 320 | E5: OG | G5: =if(D26=0,"",1+(G8/(258.6-((G8/258.2)*227.1)))) -> 1.0520145 | J5: OG | K5: 1.044
A6: Batch Volume | B6: 160 | E6: FG | G6: =if(D26=0,"",(G5-1)*(1-'004 - Elegante Elodie'!Attenuation)+1) -> 1.0015604 | J6: FG
A7: Attenuatie | B7: 0.97 | E7: ABV | G7: =if(D26=0,"",(G5-G6)*131.25/100) -> 0.06622097 | J7: ABV | K7: =IF(isblank(K6),"",(K5-K6)*131.25/100)
A8: Brouwefficientie | B8: 0.7 | E8: Plato | G8: =if(D26=0,"",SUMPRODUCT(D19:D25,F19:F25)*'004 - Elegante Elodie'!Brouwefficientie/'004 - Elegante Elodie'!Volume*100) -> 12.8625 | J8: Plato | K8: =if(ISBLANK(K5),"",(-1*616.868)+(1111.14*K5)-(630.272*POWER(K5,2))+(135.997*POWER(K5,3))) -> 10.956077
A9: OG | B9: =('004 - Elegante Elodie'!FG-1)/(1-'004 - Elegante Elodie'!Attenuation)+1 -> 1.0518409 | E9: IBU | G9: =IF(D44=0,"",R44) | J9: Brouwefficientie | K9: =iferror(K8/G8*B8,"") -> 0.59624908
A10: FG | B10: =B11*(1-B7)/(B7*131.25/100)+1 -> 1.0015552 | E10: EBC | G10: =if(G26=0,"",1.4922*P26*0.6859*1.97) -> 6.3538333
A11: ABV | B11: 0.066
A12: Plato | B12: =(-1*616.868)+(1111.14*'004 - Elegante Elodie'!OG)-(630.272*POWER('004 - Elegante Elodie'!OG,2))+(135.997*POWER('004 - Elegante Elodie'!OG,3)) -> 12.823965
A14: Granen
A15: Totaal suikers nodig | D15: ='004 - Elegante Elodie'!Plato/100*'004 - Elegante Elodie'!Volume -> 41.036687 | E15: kg
A16: Totaal granen nodig | D16: =D15/F16/'004 - Elegante Elodie'!Brouwefficientie -> 73.279798 | E16: kg | F16: 0.8
A17: Graan type | C17: Voorraad | D17: Hoeveelheid | F17: Graanrendement | G17: EBC | H17: % van totaal | I17: Lot | J17: Per hL | L17: Per batch
C18: kg | D18: Massa | E18: kg | J18: Massa | K18: =E18 -> kg | L18: Massa | M18: kg | O18: Lovibond | P18: MCU
A19: Pilsmout | C19: =iferror(VLOOKUP(A19,'Voorraadfiche Grondstoffen'!$A$2:$D$100,4,False),"") -> 50 | D19: 60 | E19: =E$18 -> kg | F19: 0.78 | G19: 3 | H19: =if(isblank(D19),"",(D19/$D$26)) -> 0.8 | J19: =IF(ISBLANK(D19),"",D19/$B$5*100) -> 18.75 | K19: =K$18 -> kg | L19: =IF(ISBLANK(D19),"",D19/$B$5*$B$6) -> 30 | M19: =M$18 -> kg | O19: =(G19*0.508+0.76)/1.3546 -> 1.6861066 | P19: =D19/kgperpound*lpergallon/$B$5*O19 -> 2.6383565
A20: Tarwemout | C20: =iferror(VLOOKUP(A20,'Voorraadfiche Grondstoffen'!$A$2:$D$100,4,False),"") -> 80 | D20: 15 | E20: =E$18 -> kg | F20: 0.8 | G20: 2 | H20: =if(isblank(D20),"",(D20/$D$26)) -> 0.2 | J20: =IF(ISBLANK(D20),"",D20/$B$5*100) -> 4.6875 | K20: =K$18 -> kg | L20: =IF(ISBLANK(D20),"",D20/$B$5*$B$6) -> 7.5 | M20: =M$18 -> kg | O20: =(G20*0.508+0.76)/1.3546 -> 1.3110881 | P20: =D20/kgperpound*lpergallon/$B$5*O20 -> 0.51288542
C21: =iferror(VLOOKUP(A21,'Voorraadfiche Grondstoffen'!$A$2:$D$100,4,False),"") | E21: =E$18 -> kg | H21: =if(isblank(D21),"",(D21/$D$26)) | J21: =IF(ISBLANK(D21),"",D21/$B$5*100) | K21: =K$18 -> kg | L21: =IF(ISBLANK(D21),"",D21/$B$5*$B$6) | M21: =M$18 -> kg | O21: =(G21*0.508+0.76)/1.3546 -> 0.56105123 | P21: =D21/kgperpound*lpergallon/$B$5*O21 -> 0
C22: =iferror(VLOOKUP(A22,'Voorraadfiche Grondstoffen'!$A$2:$D$100,4,False),"") | E22: =E$18 -> kg | H22: =if(isblank(D22),"",(D22/$D$26)) | J22: =IF(ISBLANK(D22),"",D22/$B$5*100) | K22: =K$18 -> kg | L22: =IF(ISBLANK(D22),"",D22/$B$5*$B$6) | M22: =M$18 -> kg | O22: =(G22*0.508+0.76)/1.3546 -> 0.56105123 | P22: =D22/kgperpound*lpergallon/$B$5*O22 -> 0
C23: =iferror(VLOOKUP(A23,'Voorraadfiche Grondstoffen'!$A$2:$D$100,4,False),"") | E23: =E$18 -> kg | H23: =if(isblank(D23),"",(D23/$D$26)) | J23: =IF(ISBLANK(D23),"",D23/$B$5*100) | K23: =K$18 -> kg | L23: =IF(ISBLANK(D23),"",D23/$B$5*$B$6) | M23: =M$18 -> kg | O23: =(G23*0.508+0.76)/1.3546 -> 0.56105123 | P23: =D23/kgperpound*lpergallon/$B$5*O23 -> 0
C24: =iferror(VLOOKUP(A24,'Voorraadfiche Grondstoffen'!$A$2:$D$100,4,False),"") | E24: =E$18 -> kg | H24: =if(isblank(D24),"",(D24/$D$26)) | J24: =IF(ISBLANK(D24),"",D24/$B$5*100) | K24: =K$18 -> kg | L24: =IF(ISBLANK(D24),"",D24/$B$5*$B$6) | M24: =M$18 -> kg | O24: =(G24*0.508+0.76)/1.3546 -> 0.56105123 | P24: =D24/kgperpound*lpergallon/$B$5*O24 -> 0
C25: =iferror(VLOOKUP(A25,'Voorraadfiche Grondstoffen'!$A$2:$D$100,4,False),"") | E25: =E$18 -> kg | H25: =if(isblank(D25),"",(D25/$D$26)) | J25: =IF(ISBLANK(D25),"",D25/$B$5*100) | K25: =K$18 -> kg | L25: =IF(ISBLANK(D25),"",D25/$B$5*$B$6) | M25: =M$18 -> kg | O25: =(G25*0.508+0.76)/1.3546 -> 0.56105123 | P25: =D25/kgperpound*lpergallon/$B$5*O25 -> 0
A26: TOTAL | D26: =SUM(D19:D25) -> 75 | E26: =E$18 -> kg | G26: =sum(G19:G25) -> 5 | J26: =SUM(J19:J25) -> 23.4375 | K26: =K$18 -> kg | L26: =SUM(L19:L25) -> 37.5 | M26: =M$18 -> kg | P26: =SUM(P19:P25) -> 3.151242
A28: Maisch
A29: Stap | D29: Temp | E29: Duur (min.)
A30: Protein Rest (52°C) | E30: 0
A31: Beta-Amylase Rest (63°C) | E31: 45 | F31: =IF(D31="","",D30)
A32: Alpha-Amylase Rest (72°C) | E32: 0 | F32: =IF(D32="","",D31)
A33: Mash Out (78°C) | E33: 5 | F33: =IF(D33="","",D32)
A34: TOTALS | E34: =SUM(E30:E33) -> 50 | F34: Minutes
A36: Hop
A37: Soort hop | D37: Hoeveelheid | F37: Pellet of bloem | G37: Kooktijd (min.) | H37: AA% | I37: Lot | J37: Per hL | L37: Per batch | O37: Biggness factor | P37: =1.65*POWER(0.000125,G5-1) -> 1.0338717
D38: Massa | E38: g | J38: Massa | K38: =E38 -> g | L38: Massa | M38: g | O38: Hops in oz | P38: Boil factor | Q38: Utilization | R38: IBU
E39: =E$38 -> g | F39: Pellet | J39: =IF(ISBLANK(D39),"",D39/'004 - Elegante Elodie'!Volume*100) | K39: =K$38 -> g | L39: =IF(ISBLANK(D39),"",D39/'004 - Elegante Elodie'!Volume*$B$6) | M39: =M$38 -> g | O39: =D39*ozpergram -> 0 | P39: =(1-POWER(2.71828182845904,((-0.04)*G39)))/4.15 -> 0 | Q39: =P39*$P$37 -> 0 | R39: =IF(F39="Leaf", ((H39 *O39) *Q39 * 74.9) / '004 - Elegante Elodie'!Volume*3.785, ((H39 *O39) * (Q39*1.1) * 74.9) / '004 - Elegante Elodie'!Volume*3.785) -> 0
E40: =E$38 -> g | F40: Pellet | J40: =IF(ISBLANK(D40),"",D40/'004 - Elegante Elodie'!Volume*100) | K40: =K$38 -> g | L40: =IF(ISBLANK(D40),"",D40/'004 - Elegante Elodie'!Volume*$B$6) | M40: =M$38 -> g | O40: =D40*ozpergram -> 0 | P40: =(1-POWER(2.71828182845904,((-0.04)*G40)))/4.15 -> 0 | Q40: =P40*$P$37 -> 0 | R40: =IF(F40="Leaf", ((H40 *O40) *Q40 * 74.9) / '004 - Elegante Elodie'!Volume*3.785, ((H40 *O40) * (Q40*1.1) * 74.9) / '004 - Elegante Elodie'!Volume*3.785) -> 0
E41: =E$38 -> g | F41: Pellet | J41: =IF(ISBLANK(D41),"",D41/'004 - Elegante Elodie'!Volume*100) | K41: =K$38 -> g | L41: =IF(ISBLANK(D41),"",D41/'004 - Elegante Elodie'!Volume*$B$6) | M41: =M$38 -> g | O41: =D41*ozpergram -> 0 | P41: =(1-POWER(2.71828182845904,((-0.04)*G41)))/4.15 -> 0 | Q41: =P41*$P$37 -> 0 | R41: =IF(F41="Leaf", ((H41 *O41) *Q41 * 74.9) / '004 - Elegante Elodie'!Volume*3.785, ((H41 *O41) * (Q41*1.1) * 74.9) / '004 - Elegante Elodie'!Volume*3.785) -> 0
C42: =iferror(1000*VLOOKUP(A42,'Voorraadfiche Grondstoffen'!$F$2:$I$100,4,False),"") | E42: =E$38 -> g | F42: Pellet | J42: =IF(ISBLANK(D42),"",D42/'004 - Elegante Elodie'!Volume*100) | K42: =K$38 -> g | L42: =IF(ISBLANK(D42),"",D42/'004 - Elegante Elodie'!Volume*$B$6) | M42: =M$38 -> g | O42: =D42*ozpergram -> 0 | P42: =(1-POWER(2.71828182845904,((-0.04)*G42)))/4.15 -> 0 | Q42: =P42*$P$37 -> 0 | R42: =IF(F42="Leaf", ((H42 *O42) *Q42 * 74.9) / '004 - Elegante Elodie'!Volume*3.785, ((H42 *O42) * (Q42*1.1) * 74.9) / '004 - Elegante Elodie'!Volume*3.785) -> 0
C43: =iferror(1000*VLOOKUP(A43,'Voorraadfiche Grondstoffen'!$F$2:$I$100,4,False),"") | E43: =E$38 -> g | J43: =IF(ISBLANK(D43),"",D43/'004 - Elegante Elodie'!Volume*100) | K43: =K$38 -> g | L43: =IF(ISBLANK(D43),"",D43/'004 - Elegante Elodie'!Volume*$B$6) | M43: =M$38 -> g | O43: =D43*ozpergram -> 0 | P43: =(1-POWER(2.71828182845904,((-0.04)*G43)))/4.15 -> 0 | Q43: =P43*$P$37 -> 0 | R43: =IF(F43="Leaf", ((H43 *O43) *Q43 * 74.9) / '004 - Elegante Elodie'!Volume*3.785, ((H43 *O43) * (Q43*1.1) * 74.9) / '004 - Elegante Elodie'!Volume*3.785) -> 0
A44: TOTAL | D44: =SUM(D39:D43) -> 0 | E44: =E$38 -> g | J44: =SUM(J39:J43) -> 0 | K44: =K$38 -> g | L44: =SUM(L39:L43) -> 0 | M44: =M$38 -> g | R44: =sum(R39:R43) -> 0
...

Sheet XXX - cola sour
A1: Crazy Coco
A2: Author: | B2: Tom & Sibren
A4: Gevraagd | E4: Verwacht | J4: Gemeten
A5: Volume | B5: 300 | E5: OG | G5: =if(D26=0,"",1+(G8/(258.6-((G8/258.2)*227.1)))) -> 1.0446702 | J5: OG
A6: Batch Volume | B6: 150 | E6: FG | G6: =if(D26=0,"",(G5-1)*(1-'XXX - cola sour'!Attenuation)+1) -> 1.0111675 | J6: FG
A7: Attenuatie | B7: 0.75 | E7: ABV | G7: =if(D26=0,"",(G5-G6)*131.25/100) -> 0.043972194 | J7: ABV | K7: =IF(isblank(K6),"",(K5-K6)*131.25/100)
A8: Brouwefficientie | B8: 0.65 | E8: Plato | G8: =if(D26=0,"",SUMPRODUCT(D19:D25,F19:F25)*'XXX - cola sour'!Brouwefficientie/'XXX - cola sour'!Volume*100) -> 11.115 | J8: Plato | K8: =if(ISBLANK(K5),"",(-1*616.868)+(1111.14*K5)-(630.272*POWER(K5,2))+(135.997*POWER(K5,3)))
A9: OG | B9: =('XXX - cola sour'!FG-1)/(1-'XXX - cola sour'!Attenuation)+1 -> 1.0457143 | E9: IBU | G9: =IF(D44=0,"",R44) -> 0 | J9: Brouwefficientie | K9: =iferror(K8/G8*B8,"") -> 0
A10: FG | B10: =B11*(1-B7)/(B7*131.25/100)+1 -> 1.0114286 | E10: EBC | G10: =if(G26=0,"",1.4922*P26*0.6859*1.97) -> 85.436595
A11: ABV | B11: 0.045
A12: Plato | B12: =(-1*616.868)+(1111.14*'XXX - cola sour'!OG)-(630.272*POWER('XXX - cola sour'!OG,2))+(135.997*POWER('XXX - cola sour'!OG,3)) -> 11.36659
A14: Granen
A15: Totaal suikers nodig | D15: ='XXX - cola sour'!Plato/100*'XXX - cola sour'!Volume -> 34.099771 | E15: kg
A16: Totaal granen nodig | D16: =D15/F16/'XXX - cola sour'!Brouwefficientie -> 65.576483 | E16: kg | F16: 0.8
A17: Graan type | C17: Voorraad | D17: Hoeveelheid | F17: Graanrendement | G17: EBC | H17: % van totaal | I17: Lot | J17: Per hL | L17: Per batch
C18: kg | D18: Massa | E18: kg | J18: Massa | K18: =E18 -> kg | L18: Massa | M18: kg | O18: Lovibond | P18: MCU
A19: Pilsmout | C19: =iferror(VLOOKUP(A19,'Voorraadfiche Grondstoffen'!$A$2:$D$100,4,False),"") -> 50 | D19: 50 | E19: =E$18 -> kg | F19: 0.78 | G19: 3 | H19: =if(isblank(D19),"",(D19/$D$26)) -> 0.73529412 | J19: =IF(ISBLANK(D19),"",D19/$B$5*100) -> 16.666667 | K19: =K$18 -> kg | L19: =IF(ISBLANK(D19),"",D19/$B$5*$B$6) -> 25 | M19: =M$18 -> kg | O19: =(G19*0.508+0.76)/1.3546 -> 1.6861066 | P19: =D19/kgperpound*lpergallon/$B$5*O19 -> 2.3452058
A20: Carared | C20: =iferror(VLOOKUP(A20,'Voorraadfiche Grondstoffen'!$A$2:$D$100,4,False),"") | D20: 5 | E20: =E$18 -> kg | F20: 0.78 | G20: 50 | H20: =if(isblank(D20),"",(D20/$D$26)) -> 0.073529412 | J20: =IF(ISBLANK(D20),"",D20/$B$5*100) -> 1.6666667 | K20: =K$18 -> kg | L20: =IF(ISBLANK(D20),"",D20/$B$5*$B$6) -> 2.5 | M20: =M$18 -> kg | O20: =(G20*0.508+0.76)/1.3546 -> 19.311974 | P20: =D20/kgperpound*lpergallon/$B$5*O20 -> 2.6861026
A21: Caramunich | C21: =iferror(VLOOKUP(A21,'Voorraadfiche Grondstoffen'!$A$2:$D$100,4,False),"") | D21: 5 | E21: =E$18 -> kg | F21: 0.72 | G21: 110 | H21: =if(isblank(D21),"",(D21/$D$26)) -> 0.073529412 | J21: =IF(ISBLANK(D21),"",D21/$B$5*100) -> 1.6666667 | K21: =K$18 -> kg | L21: =IF(ISBLANK(D21),"",D21/$B$5*$B$6) -> 2.5 | M21: =M$18 -> kg | O21: =(G21*0.508+0.76)/1.3546 -> 41.813081 | P21: =D21/kgperpound*lpergallon/$B$5*O21 -> 5.8157818
A22: Havervlokken | C22: =iferror(VLOOKUP(A22,'Voorraadfiche Grondstoffen'!$A$2:$D$100,4,False),"") -> 5.5 | D22: 5 | E22: =E$18 -> kg | F22: 0.78 | G22: 2 | H22: =if(isblank(D22),"",(D22/$D$26)) -> 0.073529412 | J22: =IF(ISBLANK(D22),"",D22/$B$5*100) -> 1.6666667 | K22: =K$18 -> kg | L22: =IF(ISBLANK(D22),"",D22/$B$5*$B$6) -> 2.5 | M22: =M$18 -> kg | O22: =(G22*0.508+0.76)/1.3546 -> 1.3110881 | P22: =D22/kgperpound*lpergallon/$B$5*O22 -> 0.18235926
A23: Chocolate Dark | C23: =iferror(VLOOKUP(A23,'Voorraadfiche Grondstoffen'!$A$2:$D$100,4,False),"") -> 0 | D23: 3 | E23: =E$18 -> kg | F23: 0.3 | G23: 1000 | H23: =if(isblank(D23),"",(D23/$D$26)) -> 0.044117647 | J23: =IF(ISBLANK(D23),"",D23/$B$5*100) -> 1 | K23: =K$18 -> kg | L23: =IF(ISBLANK(D23),"",D23/$B$5*$B$6) -> 1.5 | M23: =M$18 -> kg | O23: =(G23*0.508+0.76)/1.3546 -> 375.57951 | P23: =D23/kgperpound*lpergallon/$B$5*O23 -> 31.343614
C24: =iferror(VLOOKUP(A24,'Voorraadfiche Grondstoffen'!$A$2:$D$100,4,False),"") | E24: =E$18 -> kg | H24: =if(isblank(D24),"",(D24/$D$26)) | J24: =IF(ISBLANK(D24),"",D24/$B$5*100) | K24: =K$18 -> kg | L24: =IF(ISBLANK(D24),"",D24/$B$5*$B$6) | M24: =M$18 -> kg | O24: =(G24*0.508+0.76)/1.3546 -> 0.56105123 | P24: =D24/kgperpound*lpergallon/$B$5*O24 -> 0
C25: =iferror(VLOOKUP(A25,'Voorraadfiche Grondstoffen'!$A$2:$D$100,4,False),"") | E25: =E$18 -> kg | H25: =if(isblank(D25),"",(D25/$D$26)) | J25: =IF(ISBLANK(D25),"",D25/$B$5*100) | K25: =K$18 -> kg | L25: =IF(ISBLANK(D25),"",D25/$B$5*$B$6) | M25: =M$18 -> kg | O25: =(G25*0.508+0.76)/1.3546 -> 0.56105123 | P25: =D25/kgperpound*lpergallon/$B$5*O25 -> 0
A26: TOTAL | D26: =SUM(D19:D25) -> 68 | E26: =E$18 -> kg | G26: =sum(G19:G25) -> 1165 | J26: =SUM(J19:J25) -> 22.666667 | K26: =K$18 -> kg | L26: =SUM(L19:L25) -> 34 | M26: =M$18 -> kg | P26: =SUM(P19:P25) -> 42.373064
A28: Maisch
A29: Stap | D29: Temp | E29: Duur (min.)
A30: Protein Rest (52°C) | E30: 0
A31: Beta-Amylase Rest (63°C) | E31: 20 | F31: =IF(D31="","",D30)
A32: Alpha-Amylase Rest (72°C) | E32: 20 | F32: =IF(D32="","",D31)
A33: Mash Out (78°C) | E33: 5 | F33: =IF(D33="","",D32)
A34: TOTALS | E34: =SUM(E30:E33) -> 45 | F34: Minutes
A36: Hop
A37: Soort hop | D37: Hoeveelheid | F37: Pellet of bloem | G37: Kooktijd (min.) | H37: AA% | I37: Lot | J37: Per hL | L37: Per batch | O37: Biggness factor | P37: =1.65*POWER(0.000125,G5-1) -> 1.1044149
D38: Massa | E38: g | J38: Massa | K38: =E38 -> g | L38: Massa | M38: g | O38: Hops in oz | P38: Boil factor | Q38: Utilization | R38: IBU
A39: hallertau | C39: =iferror(1000*VLOOKUP(A39,'Voorraadfiche Grondstoffen'!$F$2:$I$100,4,False),"") | D39: 200 | E39: =E$38 -> g | F39: Pellet | G39: 0 | J39: =IF(ISBLANK(D39),"",D39/'XXX - cola sour'!Volume*100) -> 66.666667 | K39: =K$38 -> g | L39: =IF(ISBLANK(D39),"",D39/'XXX - cola sour'!Volume*$B$6) -> 100 | M39: =M$38 -> g | O39: =D39*ozpergram -> 7.054792 | P39: =(1-POWER(2.71828182845904,((-0.04)*G39)))/4.15 -> 0 | Q39: =P39*$P$37 -> 0 | R39: =IF(F39="Leaf", ((H39 *O39) *Q39 * 74.9) / 'XXX - cola sour'!Volume*3.785, ((H39 *O39) * (Q39*1.1) * 74.9) / 'XXX - cola sour'!Volume*3.785) -> 0
C40: =iferror(1000*VLOOKUP(A40,'Voorraadfiche Grondstoffen'!$F$2:$I$100,4,False),"") | E40: =E$38 -> g | F40: Pellet | J40: =IF(ISBLANK(D40),"",D40/'XXX - cola sour'!Volume*100) | K40: =K$38 -> g | L40: =IF(ISBLANK(D40),"",D40/'XXX - cola sour'!Volume*$B$6) | M40: =M$38 -> g | O40: =D40*ozpergram -> 0 | P40: =(1-POWER(2.71828182845904,((-0.04)*G40)))/4.15 -> 0 | Q40: =P40*$P$37 -> 0 | R40: =IF(F40="Leaf", ((H40 *O40) *Q40 * 74.9) / 'XXX - cola sour'!Volume*3.785, ((H40 *O40) * (Q40*1.1) * 74.9) / 'XXX - cola sour'!Volume*3.785) -> 0
C41: =iferror(1000*VLOOKUP(A41,'Voorraadfiche Grondstoffen'!$F$2:$I$100,4,False),"") | E41: =E$38 -> g | F41: Pellet | J41: =IF(ISBLANK(D41),"",D41/'XXX - cola sour'!Volume*100) | K41: =K$38 -> g | L41: =IF(ISBLANK(D41),"",D41/'XXX - cola sour'!Volume*$B$6) | M41: =M$38 -> g | O41: =D41*ozpergram -> 0 | P41: =(1-POWER(2.71828182845904,((-0.04)*G41)))/4.15 -> 0 | Q41: =P41*$P$37 -> 0 | R41: =IF(F41="Leaf", ((H41 *O41) *Q41 * 74.9) / 'XXX - cola sour'!Volume*3.785, ((H41 *O41) * (Q41*1.1) * 74.9) / 'XXX - cola sour'!Volume*3.785) -> 0
C42: =iferror(1000*VLOOKUP(A42,'Voorraadfiche Grondstoffen'!$F$2:$I$100,4,False),"") | E42: =E$38 -> g | F42: Pellet | J42: =IF(ISBLANK(D42),"",D42/'XXX - cola sour'!Volume*100) | K42: =K$38 -> g | L42: =IF(ISBLANK(D42),"",D42/'XXX - cola sour'!Volume*$B$6) | M42: =M$38 -> g | O42: =D42*ozpergram -> 0 | P42: =(1-POWER(2.71828182845904,((-0.04)*G42)))/4.15 -> 0 | Q42: =P42*$P$37 -> 0 | R42: =IF(F42="Leaf", ((H42 *O42) *Q42 * 74.9) / 'XXX - cola sour'!Volume*3.785, ((H42 *O42) * (Q42*1.1) * 74.9) / 'XXX - cola sour'!Volume*3.785) -> 0
C43: =iferror(1000*VLOOKUP(A43,'Voorraadfiche Grondstoffen'!$F$2:$I$100,4,False),"") | E43: =E$38 -> g | J43: =IF(ISBLANK(D43),"",D43/'XXX - cola sour'!Volume*100) | K43: =K$38 -> g | L43: =IF(ISBLANK(D43),"",D43/'XXX - cola sour'!Volume*$B$6) | M43: =M$38 -> g | O43: =D43*ozpergram -> 0 | P43: =(1-POWER(2.71828182845904,((-0.04)*G43)))/4.15 -> 0 | Q43: =P43*$P$37 -> 0 | R43: =IF(F43="Leaf", ((H43 *O43) *Q43 * 74.9) / 'XXX - cola sour'!Volume*3.785, ((H43 *O43) * (Q43*1.1) * 74.9) / 'XXX - cola sour'!Volume*3.785) -> 0
A44: TOTAL | D44: =SUM(D39:D43) -> 200 | E44: =E$38 -> g | J44: =SUM(J39:J43) -> 66.666667 | K44: =K$38 -> g | L44: =SUM(L39:L43) -> 100 | M44: =M$38 -> g | R44: =sum(R39:R43) -> 0
...

Sheet 008 - Pastry Orangette
A1: Pastry Orangette
A2: Author: | B2: Sibren
A4: Gevraagd | E4: Verwacht | J4: Gemeten
A5: Volume | B5: 180 | E5: OG | G5: =if(D26=0,"",1+(G8/(258.6-((G8/258.2)*227.1)))) -> 1.1195639 | J5: OG
A6: Batch Volume | B6: 90 | E6: FG | G6: =if(D26=0,"",(G5-1)*(1-'008 - Pastry Orangette'!Attenuation)+1) -> 1.029891 | J6: FG
A7: Attenuatie | B7: 0.75 | E7: ABV | G7: =if(D26=0,"",(G5-G6)*131.25/100) -> 0.11769571 | J7: ABV | K7: =IF(isblank(K6),"",(K5-K6)*131.25/100)
A8: Brouwefficientie | B8: 0.65 | E8: Plato | G8: =if(D26=0,"",SUMPRODUCT(D19:D25,F19:F25)*'008 - Pastry Orangette'!Brouwefficientie/'008 - Pastry Orangette'!Volume*100) -> 27.977083 | J8: Plato | K8: =if(ISBLANK(K5),"",(-1*616.868)+(1111.14*K5)-(630.272*POWER(K5,2))+(135.997*POWER(K5,3)))
A9: OG | B9: =('008 - Pastry Orangette'!FG-1)/(1-'008 - Pastry Orangette'!Attenuation)+1 -> 1.1219048 | E9: IBU | G9: =IF(D44=0,"",R44) -> 31.080295 | J9: Brouwefficientie | K9: =iferror(K8/G8*B8,"") -> 0
A10: FG | B10: =B11*(1-B7)/(B7*131.25/100)+1 -> 1.0304762 | E10: EBC | G10: =if(G26=0,"",1.4922*P26*0.6859*1.97) -> 220.05091
A11: ABV | B11: 0.12
A12: Plato | B12: =(-1*616.868)+(1111.14*'008 - Pastry Orangette'!OG)-(630.272*POWER('008 - Pastry Orangette'!OG,2))+(135.997*POWER('008 - Pastry Orangette'!OG,3)) -> 28.463092
A14: Granen
A15: Totaal suikers nodig | D15: ='008 - Pastry Orangette'!Plato/100*'008 - Pastry Orangette'!Volume -> 51.233565 | E15: kg
A16: Totaal granen nodig | D16: =D15/F16/'008 - Pastry Orangette'!Brouwefficientie -> 98.526086 | E16: kg | F16: 0.8
A17: Graan type | C17: Voorraad | D17: Hoeveelheid | F17: Graanrendement | G17: EBC | H17: % van totaal | I17: Lot | J17: Per hL | L17: Per batch
C18: kg | D18: Massa | E18: kg | J18: Massa | K18: =E18 -> kg | L18: Massa | M18: kg | O18: Lovibond | P18: MCU
